Workbook

Sheet راهنما
A1: مدل مالی خط کسب‌وکار جدید اسمارتک — حلقهٔ بستهٔ تصمیم کمپین
A2: نسخهٔ v0.8 · ۳۱ شهریور ۱۴۰۵ · واحد پول: میلیون تومان · افق: ۲۴ ماه
A5: چه چیزی در v0.8 عوض شد — مهم
A6: رشد فهرست قیمت به هنجار بازار لنگر شد. | B6: رشد سالانهٔ فهرست قیمت از ۲۰/۴۰/۴۰ درصد به ۳۰/۳۲٫۵/۳۵ درصد (بدبین/پایه/خوش‌بین) رسید — بازه‌ای که I-05 برای ابزارهای داخلی گزارش کرد. چون تورم هزینه ۴۰٪ است، حاشیهٔ هر مشتری سال به سال فشرده می‌شود.
A7: ⚠ وزن این شاهد پایین است. | B7: I-05 کسب‌وکار کوچکی دارد. این شاهد فقط چون مدل را محافظه‌کارانه‌تر می‌کند پذیرفته شد: سود عملیاتی سال دوم پایه ۸۰۱ میلیون بدتر شد.
A8: چه چیزی در v0.7 عوض شد
A9: نرخ رشد از حدس به شاهد تبدیل شد. | B9: v0.6 رشد ۷۰٪ را برآورد تیم گرفته بود. v0.7 آن را با ۴۴٪ جایگزین کرد — عددی که گزارش سالانهٔ ۱۴۰۴ دیجی‌کالا مستقیما می‌دهد. نتیجه: همهٔ اندازه‌ها حدود ۲۹٪ کوچک‌تر شدند.
A10: چه چیزی در v0.6 عوض شد
A11: فروش فازی جایگزین فروش حلقهٔ کامل شد. | B11: سه فاز جدا فروخته می‌شوند: Verifier → Designer → Simulator. درآمد هر مشتری با عرضهٔ هر فاز پلکانی بالا می‌رود.
A12: زمان‌بندی عرضه. | B12: فاز ۱ در ماه ۶، فاز ۲ در ماه ۱۱، فاز ۳ در ماه ۱۹. تا ماه ۱۱ فقط ۳۰٪ قیمت وصول می‌شود و تا ماه ۱۹ فقط ۷۵٪.
A13: هزینهٔ توسعه هم فازی شد. | B13: به‌جای ۴۰ نفر-ماه در ۶ ماه، سه موج توسعه هم‌زمان با سه فاز.
A14: بستهٔ کامل ۲۳٪ ارزان‌تر از خرید تکه‌تکه است. | B14: مجموع سهم سه فاز ۱۳۰٪ است؛ بستهٔ کامل ۱۰۰٪. انگیزهٔ بسته‌شدن حلقه.
A15: چه چیزی در v0.5 عوض شد
A16: اندازهٔ مرچنت‌ها از ۱۴۰۳ به ۱۴۰۵ آورده شد. | B16: شاهد صورت مالی برای ۱۴۰۳ است؛ مدل در ۱۴۰۵ اجرا می‌شود. رشد اسمی دو سال اعمال شد (از v0.7 با نرخ ۴۴٪).
A17: چه چیزی در v0.4 عوض شد
A18: اندازهٔ سگمنت مگا شاهد عمومی پیدا کرد. | B18: درآمد عملیاتی گروه دیجی‌کالا در سال مالی ۱۴۰۳: ۳۰٬۴۲۳ میلیارد تومان [دیجیاتو، ۱۰ خرداد ۱۴۰۴].
A19: کنترل سود خالص مشتری اضافه شد. | B19: لایسنس ما چند درصد سود خالص مشتری را می‌خورد؟ حاشیهٔ سود خالص دیجی‌کالا زیر ۲٪ است.
A20: ⚠ ابهام باز: قاعدهٔ ۴٪. | B20: I-05 نگفت ۴٪ از درآمد عملیاتی است یا از GMV — و خود قاعده، سرانگشتی یک نفر با کسب‌وکار کوچک است. این تک‌ورودی، SAM را چند برابر جابه‌جا می‌کند.
A21: چه چیزی در v0.3 عوض شد
A22: بازار هدف از پایین به بالا ساخته شد. | B22: سه سگمنت مرچنت با تعداد مشخص · SAM جمع سگمنت‌هاست، نه درصدی از یک عدد کلان.
A23: سقف سوم اضافه شد: تعداد مرچنت موجود. | B23: قیف فروش نمی‌تواند بیشتر از تعداد مرچنت‌های آن سگمنت قرارداد بسازد.
A24: هر سناریو یک سگمنت هدف دارد. | B24: بدبین: متوسط · پایه: بزرگ · خوش‌بین: مگا — نه یک «مشتری نماینده» دلبخواه.
A25: سه سناریو، سه مدل کامل و جدا. | B25: هر سناریو شیت ۲۴ماههٔ خودش را دارد؛ دیگر لازم نیست مفروضات را دستی عوض کنی.
A26: نرخ نفر-ماه از حقوق مشتق می‌شود. | B26: حقوق ناخالص × ضریب سرریز × ترکیب تیم. دیگر یک عدد ادعایی نیست.
A27: تورم هزینه و رشد فهرست قیمت وارد شد. | B27: نرخ نفر-ماه سالی ۴۰٪ بالا می‌رود. اگر قیمت با آن بالا نرود، حاشیه می‌ریزد.
A28: قیمت از اندازهٔ مشتری مشتق می‌شود. | B28: لایسنس = خرج تبلیغات × سهم عبوری از حلقه × نرخ لایسنس. پله‌ها بستهٔ فروش‌اند، محرک مدل نیستند.
A29: پشتیبانی On-Premise گران‌تر حساب شد. | B29: نسخه‌بندی و مدل محلی، ساعت پشتیبانی بیشتری می‌خواهد و سقف ظرفیت را پایین می‌آورد.
A31: چطور استفاده کنی
A32: دو شیت قابل ویرایش: «مفروضات مشترک» و «سناریوها». | B32: بقیه فرمول‌اند.
A33: سلول زرد = عددی که هنوز نداریم. | B33: تا پر نشود، خروجی مدل ساختار است نه نتیجه.
A34: رنگ متن معنا دارد. | B34: آبی = ورودی دستی · مشکی = فرمول · سبز = ارجاع به شیت دیگر
A35: اول «مقایسهٔ سناریوها» را ببین. | B35: همهٔ نتیجه‌ها آنجا کنار هم‌اند.
A37: هشدار روش‌شناختی — مهم
A38: سناریوی خوش‌بین، مدل را خیلی راحت سودده می‌کند. | B38: چون فرض می‌کند مشتری سالی ۲٬۰۰۰ میلیارد تومان تبلیغات خرج می‌کند. این عدد هنوز شاهد ندارد.
A39: آنچه در دفاع گفته می‌شود، ستون «پایه» است. | B39: خوش‌بین فقط نشان می‌دهد سقف کجاست، نه اینکه نتیجه چیست.
A40: اگر یک ورودی مدل را از «جواب نمی‌دهد» به «خیلی راحت» ببرد، | B40: همان ورودی است که باید اول اثبات شود. اینجا آن ورودی، خرج تبلیغات مشتری است.
A42: عددهایی که هنوز نداریم | B42: از کجا می‌آید
A43: خرج تبلیغات سالانهٔ مشتریان هدف — بازهٔ بی‌نام | B43: درخواست از اسمارتک — تسک T-05 · مهم‌ترین عدد مدل
A44: سهم بودجهٔ عبوری از حلقه از کل خرج | B44: پایلوت · تا آن‌موقع فرض
A45: نرخ ریزش سالانه | B45: اسمارتک — تسک T-05
...

Sheet مفروضات مشترک
A1: مفروضات مشترک — یکسان در هر سه سناریو
A2: آنچه بین سناریوها فرق می‌کند در شیت «سناریوها» است.
A4: پارامتر | B4: مقدار | C4: واحد | D4: برچسب | E4: منبع یا منطق
A5: الف) حقوق و نرخ نفر-ماه — تأییدشدهٔ مالک سند، ۲۷ شهریور ۱۴۰۵
A6: حقوق ناخالص ماهانه — مهندس ارشد | B6: 140 | C6: م.تومان/ماه | D6: برآورد تیم | E6: تأیید مالک سند در ۲۷ شهریور ۱۴۰۵
A7: حقوق ناخالص ماهانه — مهندس یادگیری ماشین | B7: 160 | C7: م.تومان/ماه | D7: برآورد تیم | E7: تأیید مالک سند در ۲۷ شهریور ۱۴۰۵
A8: حقوق ناخالص ماهانه — پشتیبانی و موفقیت مشتری | B8: 80 | C8: م.تومان/ماه | D8: برآورد تیم | E8: تأیید مالک سند در ۲۷ شهریور ۱۴۰۵
A9: ضریب سرریز روی حقوق | B9: 1.4 | C9: ضریب | D9: برآورد تیم | E9: بیمه، فضا، ابزار، مرخصی
A10: تورم سالانهٔ هزینهٔ نیروی انسانی | B10: 0.4 | C10: درصد | D10: برآورد تیم | E10: تأیید مالک سند؛ روی نرخ نفر-ماه هر سال اعمال می‌شود
A11: سهم مهندس ارشد در تیم توسعه | B11: 0.6 | C11: درصد | D11: برآورد تیم | E11: ترکیب سنیوریتی دورهٔ ساخت
A12: ب) فازبندی عرضه — تصمیم ۳ اصلاح‌شده
A13: سهم قیمت فاز ۱ (Verifier) از بستهٔ کامل | B13: 0.3 | C13: درصد | D13: برآورد تیم | E13: کم‌هزینه‌ترین ساخت، ملموس‌ترین ارزش، نقطهٔ ورود کم‌ریسک — I-05
A14: سهم تجمعی پس از فاز ۲ (+ Designer) | B14: 0.75 | C14: درصد | D14: برآورد تیم | E14: Designer بیشترین ارزش را دارد: خروجی‌اش خودِ طرح است
A15: سهم تجمعی پس از فاز ۳ (+ Simulator) | B15: 1 | C15: درصد | D15: برآورد تیم | E15: بستهٔ کامل = مبنای ۱۰۰٪
A16: ماه عرضهٔ فاز ۱ | B16: 6 | C16: ماه | D16: برآورد تیم | E16: پنج ماه ساخت، عرضه در ماه ۶
A17: ماه عرضهٔ فاز ۲ | B17: 11 | C17: ماه | D17: برآورد تیم | E17: هفت ماه پس از فاز ۱
A18: ماه عرضهٔ فاز ۳ | B18: 19 | C18: ماه | D18: برآورد تیم | E18: سنگین‌ترین ساخت — I-05: پیچیدگی فنی بالا
A19: ج) ساخت و تیم
A20: نفر-ماه توسعه فاز ۱ | B20: 10 | C20: نفر-ماه | D20: برآورد تیم | E20: کارت راستی‌آزمایی با ورود دستی پیش‌بینی
A21: نفر-ماه توسعه فاز ۲ | B21: 18 | C21: نفر-ماه | D21: برآورد تیم | E21: سنگین‌ترین جزء ارزش
A22: نفر-ماه توسعه فاز ۳ | B22: 20 | C22: نفر-ماه | D22: برآورد تیم | E22: موتور شبیه‌سازی — سند محصول ۲ §۵.۷.۱
A23: مدت هر موج توسعه | B23: 5 | C23: ماه | D23: برآورد تیم | E23: هر فاز پنج ماه پیش از عرضه‌اش ساخته می‌شود
A24: ماه شروع فروش | B24: 6 | C24: ماه | D24: برآورد تیم | E24: هم‌زمان با عرضهٔ فاز ۱
A25: سهم زمان تیم نگهداشت که به پشتیبانی مشتری می‌رسد | B25: 0.6 | C25: درصد | D25: برآورد تیم | E25: بقیه صرف رفع اشکال و نسخهٔ بعدی می‌شود
A26: د) استقرار و ظرفیت
A27: ظرفیت استقرار هم‌زمان | B27: 3 | C27: مشتری | D27: شاهد | E27: سند محصول ۲ §۵.۶ و محصول ۳ §۵.۶
A28: مدت استقرار هر مشتری | B28: 1.5 | C28: ماه | D28: فرض اثبات‌نشده | E28: اندازه‌گیری در پایلوت
A29: نفر-روز استقرار هر مشتری | B29: 20 | C29: نفر-روز | D29: فرض اثبات‌نشده | E29: اندازه‌گیری در پایلوت
A30: درآمد استقرار — ابری | B30: 150 | C30: م.تومان یک‌باره | D30: فرض اثبات‌نشده | E30: برآورد تیم؛ آزمون در پایلوت
A31: درآمد استقرار — On-Premise | B31: 400 | C31: م.تومان یک‌باره | D31: فرض اثبات‌نشده | E31: نفر-روز بیشتر؛ سرور از سمت مرچنت
A32: سهم مشتریان On-Premise | B32: 0.3 | C32: درصد | D32: فرض اثبات‌نشده | E32: I-04: دادهٔ هش‌شده و حساسیت امنیتی
A33: ه) پشتیبانی و زیرساخت
A34: نفر-ساعت پشتیبانی ماهانه — مشتری ابری | B34: 16 | C34: نفر-ساعت | D34: فرض اثبات‌نشده | E34: جزء H فرمول Cvar سند محصول ۳
A35: نفر-ساعت پشتیبانی ماهانه — مشتری On-Premise | B35: 24 | C35: نفر-ساعت | D35: فرض اثبات‌نشده | E35: نسخه‌بندی و مدل محلی، بار بیشتری دارد
A36: نفر-ساعت پشتیبانی اضافی به‌ازای هر ۱۰۰ میلیارد خرج مشتری | B36: 8 | C36: نفر-ساعت/ماه | D36: فرض اثبات‌نشده | E36: مشتری بزرگ‌تر خدمت بیشتری می‌خواهد — SLA، مدیر حساب، کار سفارشی
A37: هزینهٔ زیرساخت ماهانه — مشتری ابری | B37: 8 | C37: م.تومان | D37: فرض اثبات‌نشده | E37: اندازه‌گیری در پایلوت
A38: هزینهٔ زیرساخت ماهانه — مشتری On-Premise | B38: 1 | C38: م.تومان | D38: برآورد تیم | E38: سرور از سمت مرچنت تأمین می‌شود
A39: هزینهٔ جذب و فروش هر قرارداد (CAC) | B39: 60 | C39: م.تومان | D39: فرض اثبات‌نشده | E39: برآورد تیم
A40: و) ترجمهٔ اندازهٔ مشتری به گردش مالی — قاعدهٔ I-05
A41: سهم بازاریابی از گردش مالی مرچنت | B41: 0.04 | C41: درصد | D41: گفتهٔ مشارکت‌کننده | E41: I-05، ۲۷ شهریور ۱۴۰۵ — شامل هزینهٔ افراد تیم بازاریابی · نیازمند کنترل با منبع دوم
...

Sheet سناریوها
A1: سه سناریو — تفاوت در سطح محرک، نه در درصد رشد
A2: هر ستون یک روایت کامل است. سناریوی بد فقط «مشتری کمتر» نیست؛ نگهداشت سنگین‌تر و قیمت‌پذیری کمتر هم دارد.
B4: محرک | C4: بدبین | D4: پایه | E4: خوش‌بین | F4: روایتی که این ستون را می‌سازد
B5: الف) سگمنت هدف و قیمت
B6: خرج تبلیغات سالانهٔ مشتری نماینده | C6: ='بازار هدف'!$F$7 -> 46.44864 | D6: ='بازار هدف'!$F$6 -> 174.1824 | E6: ='بازار هدف'!$F$5 -> 1765.0483 | F6: بدبین: سگمنت متوسط · پایه: سگمنت بزرگ · خوش‌بین: سگمنت مگا — از شیت بازار هدف
B7: تعداد مرچنت موجود در سگمنت هدف | C7: ='بازار هدف'!$E$7 -> 30 | D7: ='بازار هدف'!$E$6 -> 10 | E7: ='بازار هدف'!$E$5 -> 1 | F7: سقف سوم مدل: قیف نمی‌تواند بیشتر از تعداد موجود قرارداد بسازد
B8: سهم بودجهٔ عبوری از حلقه | C8: 0.2 | D8: 0.3 | E8: 0.4 | F8: فقط بودجهٔ کمپین‌هایی که طرحشان از ایستگاه ۱ بیرون آمده
B9: نرخ لایسنس از بودجهٔ عبوری | C9: 0.03 | D9: 0.04 | E9: 0.05 | F9: کنترل متقابل: معادلش از کل خرج، زیر سقف ۳–۵٪ اعلام‌شدهٔ I-03 بماند
B10: رشد سالانهٔ فهرست قیمت | C10: 0.3 | D10: 0.325 | E10: 0.35 | F10: گفتهٔ مشارکت‌کننده I-05 (۳۱ شهریور ۱۴۰۵): لایسنس ابزارهای داخلی در قرارداد سالانه معمولا ۳۰ تا ۳۵ درصد در سال افزایش می‌یابد. هر سه سناریو درون همین بازه‌اند: کف، میانه، سقف. تورم هزینه ۴۰٪ است، پس حاشیه هر سال فشرده می‌شود
B11: ب) قیف فروش
B12: لید واجد شرایط در ماه | C12: 2 | D12: 4 | E12: 6 | F12: دسترسی به مشتریان فعلی و معرفی مدیر حساب
B13: نرخ تبدیل لید به جلسهٔ ارزیابی | C13: 0.4 | D13: 0.5 | E13: 0.6 | F13: اعتماد انباشتهٔ اینترک
B14: نرخ تبدیل جلسه به قرارداد | C14: 0.15 | D14: 0.25 | E14: 0.35 | F14: محرک پرحساسیت — نتیجهٔ پایلوت تعیینش می‌کند
B15: طول چرخهٔ فروش | C15: 5 | D15: 3 | E15: 2 | F15: On-Premise امضاکنندهٔ IT اضافه می‌کند و چرخه را طولانی‌تر می‌کند
B16: نرخ ریزش سالانه | C16: 0.25 | D16: 0.15 | E16: 0.1 | F16: لازم از T-05
B17: ج) هزینهٔ ثابت
B18: تعداد نفرات تیم نگهداشت پس از عرضه | C18: 5 | D18: 3 | E18: 3 | F18: بدبین: محصول بیشتر از انتظار نگهداری می‌خواهد
B20: چرا سناریوی بد این شکل است
B21: اگر در سناریوی بد فقط تعداد مشتری را کم کنیم و قیمت و هزینه را دست‌نخورده بگذاریم، سناریوی بد صادقانه نیست. واقعیت سناریوی بد این است: مشتری کوچک‌تر، محصول پرنگهداری‌تر، و مقاومت در برابر تعدیل سالانهٔ قیمت.

Sheet بازار هدف
A1: بازار هدف — از پایین به بالا، سگمنت به سگمنت
A2: واحد گردش مالی: همت (هزار میلیارد تومان) · واحد لایسنس و SAM: میلیون تومان · قیمت‌گذاری این شیت با پارامترهای سناریوی «پایه» حساب شده.
B4: سگمنت | C4: اندازه در ۱۴۰۳ (همت) | D4: اندازه در ۱۴۰۵ (همت) | E4: تعداد مرچنت | F4: خرج تبلیغات سالانه (میلیارد) | G4: لایسنس سالانه | H4: نفر-ساعت پشتیبانی/ماه | I4: SAM سگمنت | J4: نفر لازم برای پوشش | K4: لایسنس ÷ سود خالص | L4: شاهد و برچسب
B5: مگا | C5: 30.4 | D5: =C5*(1+'مفروضات مشترک'!$B$42)^'مفروضات مشترک'!$B$43 -> 63.03744 | E5: 1 | F5: =D5*1000*'مفروضات مشترک'!$B$41*'مفروضات مشترک'!$B$45 -> 1765.0483 | G5: =F5*1000*سناریوها!$D$8*سناریوها!$D$9 -> 21180.58 | H5: ='مفروضات مشترک'!$B$34*(1-'مفروضات مشترک'!$B$32)+'مفروضات مشترک'!$B$35*'مفروضات مشترک'!$B$32+'مفروضات مشترک'!$B$36*F5/100 -> 159.60387 | I5: =E5*G5 -> 21180.58 | J5: =E5*H5/('مفروضات مشترک'!$B$25*160) -> 1.6625403 | K5: =G5/1000/(D5*1000*'مفروضات مشترک'!$B$44) -> 0.0168 | L5: ⭐ شاهد: درآمد عملیاتی گروه دیجی‌کالا در سال مالی ۱۴۰۳ = ۳۰٬۴۲۳ میلیارد تومان [دیجیاتو، ۱۰ خرداد ۱۴۰۴]
B6: بزرگ | C6: 3 | D6: =C6*(1+'مفروضات مشترک'!$B$42)^'مفروضات مشترک'!$B$43 -> 6.2208 | E6: 10 | F6: =D6*1000*'مفروضات مشترک'!$B$41*'مفروضات مشترک'!$B$45 -> 174.1824 | G6: =F6*1000*سناریوها!$D$8*سناریوها!$D$9 -> 2090.1888 | H6: ='مفروضات مشترک'!$B$34*(1-'مفروضات مشترک'!$B$32)+'مفروضات مشترک'!$B$35*'مفروضات مشترک'!$B$32+'مفروضات مشترک'!$B$36*F6/100 -> 32.334592 | I6: =E6*G6 -> 20901.888 | J6: =E6*H6/('مفروضات مشترک'!$B$25*160) -> 3.3681867 | K6: =G6/1000/(D6*1000*'مفروضات مشترک'!$B$44) -> 0.0168 | L6: تعداد: گفتهٔ مالک سند — «دست‌کم ۸ تا ۱۲ مرچنت بزرگ» · اندازهٔ نماینده: فرض اثبات‌نشده
B7: متوسط | C7: 0.8 | D7: =C7*(1+'مفروضات مشترک'!$B$42)^'مفروضات مشترک'!$B$43 -> 1.65888 | E7: 30 | F7: =D7*1000*'مفروضات مشترک'!$B$41*'مفروضات مشترک'!$B$45 -> 46.44864 | G7: =F7*1000*سناریوها!$D$8*سناریوها!$D$9 -> 557.38368 | H7: ='مفروضات مشترک'!$B$34*(1-'مفروضات مشترک'!$B$32)+'مفروضات مشترک'!$B$35*'مفروضات مشترک'!$B$32+'مفروضات مشترک'!$B$36*F7/100 -> 22.115891 | I7: =E7*G7 -> 16721.51 | J7: =E7*H7/('مفروضات مشترک'!$B$25*160) -> 6.911216 | K7: =G7/1000/(D7*1000*'مفروضات مشترک'!$B$44) -> 0.0168 | L7: فرض اثبات‌نشده — کنترل با شاهد داشبورد: مشتریان پولی ادتریس ۷۰ تا ۸۰ [گفتهٔ مشارکت‌کننده، مرداد ۱۴۰۵]
B8: جمع بازار هدف | E8: =SUM(E5:E7) -> 41 | I8: =SUM(I5:I7) -> 58803.978 | J8: =SUM(J5:J7) -> 11.941943 | L8: SAM = جمع (تعداد مرچنت × لایسنس آن سگمنت) — نه درصدی از یک عدد کلان
B10: آنچه این جدول می‌گوید
B11: SAM سالانه — کل بازار هدف | E11: =I8 -> 58803.978 | L11: اگر همهٔ مرچنت‌های واجد شرایط خریدار شوند
B12: SAM بدون سگمنت متوسط | E12: =I5+I6 -> 42082.468 | L12: محافظه‌کارانه‌تر: فقط مگا و بزرگ
B13: نفر لازم برای پوشش کل بازار هدف | E13: =J8 -> 11.941943 | L13: ⚠ نقشهٔ رشد این خط، نقشهٔ استخدام است
B14: سهم مگا از کل SAM | E14: =IF(I8=0,0,I5/I8) -> 0.36018957 | L14: اگر بالای ۴۰٪ باشد، ریسک تمرکز جدی است
B15: حداقل گردش مالی برای ورود به ICP | E15: ='اقتصاد واحد'!$D$25 -> 2060.8214 | L15: همت — هر سگمنتی زیر این عدد، در ICP نیست
B17: قاعدهٔ ترجمه
B18: خرج تبلیغات سالانه = گردش مالی × ۴٪ (سهم بازاریابی، شامل حقوق تیم — گفتهٔ I-05) × ۷۰٪ (سهم رسانه از پاکت — فرض اثبات‌نشده)
B19: ⚠ ابهام باز و مهم: I-05 نگفت ۴٪ از «درآمد عملیاتی» است یا از «ارزش کل معاملات (GMV)». این جدول مبنا را درآمد عملیاتی گرفته، چون تنها عدد حسابرسی‌شدهٔ عمومی همان است. اگر مبنا GMV باشد، همهٔ لایسنس‌ها و SAM حدود ۲.۶ برابر می‌شوند.

Sheet اقتصاد واحد
A1: اقتصاد واحد — به‌ازای یک مشتری، در هر سه سناریو
A2: واحد در این مدل = یک شرکت تبلیغ‌کننده با قرارداد فعال. اعداد سال اول‌اند؛ اثر تورم در شیت‌های ۲۴ماهه می‌آید.
B4: ردیف | C4: بدبین | D4: پایه | E4: خوش‌بین | F4: فرمول یا منبع
B5: درآمد
B6: خرج تبلیغات سالانهٔ مشتری | C6: =سناریوها!$C$6 -> 46.44864 | D6: =سناریوها!$D$6 -> 174.1824 | E6: =سناریوها!$E$6 -> 1765.0483 | F6: از شیت سناریوها — میلیارد تومان
B7: بودجهٔ عبوری از حلقه — سالانه | C7: =سناریوها!$C$6*1000*سناریوها!$C$8 -> 9289.728 | D7: =سناریوها!$D$6*1000*سناریوها!$D$8 -> 52254.72 | E7: =سناریوها!$E$6*1000*سناریوها!$E$8 -> 706019.33 | F7: خرج سالانه (میلیارد) × ۱۰۰۰ × سهم عبوری
B8: لایسنس سالانه (ARPA) | C8: =C7*سناریوها!$C$9 -> 278.69184 | D8: =D7*سناریوها!$D$9 -> 2090.1888 | E8: =E7*سناریوها!$E$9 -> 35300.966 | F8: بودجهٔ عبوری × نرخ لایسنس
B9: معادل درصد از کل خرج تبلیغات مشتری | C9: =C8/(سناریوها!$C$6*1000) -> 0.006 | D9: =D8/(سناریوها!$D$6*1000) -> 0.012 | E9: =E8/(سناریوها!$E$6*1000) -> 0.02 | F9: کنترل متقابل — نه فرمول قیمت
B10: کنترل در برابر شاهد تمایل به پرداخت | C10: =IF(C9>0.05,"⚠ بالای سقف ۵٪ اعلام‌شدهٔ I-03",IF(C9>0.016,"بالای لنگر ۱.۶٪ I-04 — نیازمند دفاع صریح","زیر لنگر ۱.۶٪ I-04")) -> زیر لنگر ۱.۶٪ I-04 | D10: =IF(D9>0.05,"⚠ بالای سقف ۵٪ اعلام‌شدهٔ I-03",IF(D9>0.016,"بالای لنگر ۱.۶٪ I-04 — نیازمند دفاع صریح","زیر لنگر ۱.۶٪ I-04")) -> زیر لنگر ۱.۶٪ I-04 | E10: =IF(E9>0.05,"⚠ بالای سقف ۵٪ اعلام‌شدهٔ I-03",IF(E9>0.016,"بالای لنگر ۱.۶٪ I-04 — نیازمند دفاع صریح","زیر لنگر ۱.۶٪ I-04")) -> بالای لنگر ۱.۶٪ I-04 — نیازمند دفاع صریح | F10: I-04: ۱.۶٪ · I-03: سقف ۳ تا ۵٪
B11: لایسنس ماهانه | C11: =C8/12 -> 23.22432 | D11: =D8/12 -> 174.1824 | E11: =E8/12 -> 2941.7472 | F11: ARPA ÷ ۱۲
B12: درآمد استقرار — میانگین وزنی | C12: ='مفروضات مشترک'!$B$31*'مفروضات مشترک'!$B$32+'مفروضات مشترک'!$B$30*(1-'مفروضات مشترک'!$B$32) -> 225 | D12: ='مفروضات مشترک'!$B$31*'مفروضات مشترک'!$B$32+'مفروضات مشترک'!$B$30*(1-'مفروضات مشترک'!$B$32) -> 225 | E12: ='مفروضات مشترک'!$B$31*'مفروضات مشترک'!$B$32+'مفروضات مشترک'!$B$30*(1-'مفروضات مشترک'!$B$32) -> 225 | F12: On-Prem × سهمش + ابری × بقیه
B13: هزینهٔ متغیر
B14: نفر-ساعت پشتیبانی پایه — میانگین وزنی | C14: ='مفروضات مشترک'!$B$35*'مفروضات مشترک'!$B$32+'مفروضات مشترک'!$B$34*(1-'مفروضات مشترک'!$B$32) -> 18.4 | D14: ='مفروضات مشترک'!$B$35*'مفروضات مشترک'!$B$32+'مفروضات مشترک'!$B$34*(1-'مفروضات مشترک'!$B$32) -> 18.4 | E14: ='مفروضات مشترک'!$B$35*'مفروضات مشترک'!$B$32+'مفروضات مشترک'!$B$34*(1-'مفروضات مشترک'!$B$32) -> 18.4 | F14: On-Prem بار پشتیبانی بیشتری دارد
B15: نفر-ساعت پشتیبانی ماهانه — میانگین وزنی | C15: =C14+'مفروضات مشترک'!$B$36*C6/100 -> 22.115891 | D15: =D14+'مفروضات مشترک'!$B$36*D6/100 -> 32.334592 | E15: =E14+'مفروضات مشترک'!$B$36*E6/100 -> 159.60387 | F15: پایه + مقیاس‌پذیر با اندازهٔ مشتری
B16: هزینهٔ پشتیبانی ماهانه | C16: =C15/160*'مفروضات مشترک'!$B$53 -> 24.511779 | D16: =D15/160*'مفروضات مشترک'!$B$53 -> 35.837506 | E16: =E15/160*'مفروضات مشترک'!$B$53 -> 176.89428 | F16: نفر-ساعت ÷ ۱۶۰ × نرخ نفر-ماه نگهداشت
B17: هزینهٔ زیرساخت ماهانه — میانگین وزنی | C17: ='مفروضات مشترک'!$B$38*'مفروضات مشترک'!$B$32+'مفروضات مشترک'!$B$37*(1-'مفروضات مشترک'!$B$32) -> 5.9 | D17: ='مفروضات مشترک'!$B$38*'مفروضات مشترک'!$B$32+'مفروضات مشترک'!$B$37*(1-'مفروضات مشترک'!$B$32) -> 5.9 | E17: ='مفروضات مشترک'!$B$38*'مفروضات مشترک'!$B$32+'مفروضات مشترک'!$B$37*(1-'مفروضات مشترک'!$B$32) -> 5.9 | F17: On-Prem سرور از مرچنت است، پس هزینهٔ ما کمتر
B18: جمع هزینهٔ متغیر ماهانه | C18: =C16+C17 -> 30.411779 | D18: =D16+D17 -> 41.737506 | E18: =E16+E17 -> 182.79428 | F18: پشتیبانی + زیرساخت
B19: حاشیه
B20: حاشیهٔ مشارکت ماهانه | C20: =C11-C18 -> -7.1874594 | D20: =D11-D18 -> 132.44489 | E20: =E11-E18 -> 2758.9529 | F20: لایسنس ماهانه − هزینهٔ متغیر ماهانه
B21: حاشیهٔ مشارکت — درصد | C21: =IF(C11=0,0,C20/C11) -> -0.30947986 | D21: =IF(D11=0,0,D20/D11) -> 0.76038046 | E21: =IF(E11=0,0,E20/E11) -> 0.937862 | F21: هدف سند محصول ۲: حداقل ۵۰٪
B22: کنترل هدف حاشیه | C22: =IF(C21>=0.5,"عبور","⚠ زیر هدف ۵۰٪") -> ⚠ زیر هدف ۵۰٪ | D22: =IF(D21>=0.5,"عبور","⚠ زیر هدف ۵۰٪") -> عبور | E22: =IF(E21>=0.5,"عبور","⚠ زیر هدف ۵۰٪") -> عبور | F22: گیت عددی
B23: حداقل خرج تبلیغات مشتری برای حاشیهٔ ۵۰٪ | C23: =IF((1000*سناریوها!$C$8*سناریوها!$C$9/12-'مفروضات مشترک'!$B$36*'مفروضات مشترک'!$B$53/16000)<=0,"با این نرخ قیمت هیچ اندازه‌ای جواب نمی‌دهد",2*(C14*'مفروضات مشترک'!$B$53/160+C17)/(1000*سناریوها!$C$8*سناریوها!$C$9/12-'مفروضات مشترک'!$B$36*'مفروضات مشترک'!$B$53/16000)) -> 127.84441 | D23: =IF((1000*سناریوها!$D$8*سناریوها!$D$9/12-'مفروضات مشترک'!$B$36*'مفروضات مشترک'!$B$53/16000)<=0,"با این نرخ قیمت هیچ اندازه‌ای جواب نمی‌دهد",2*(D14*'مفروضات مشترک'!$B$53/160+D17)/(1000*سناریوها!$D$8*سناریوها!$D$9/12-'مفروضات مشترک'!$B$36*'مفروضات مشترک'!$B$53/16000)) -> 57.702999 | E23: =IF((1000*سناریوها!$E$8*سناریوها!$E$9/12-'مفروضات مشترک'!$B$36*'مفروضات مشترک'!$B$53/16000)<=0,"با این نرخ قیمت هیچ اندازه‌ای جواب نمی‌دهد",2*(E14*'مفروضات مشترک'!$B$53/160+E17)/(1000*سناریوها!$E$8*سناریوها!$E$9/12-'مفروضات مشترک'!$B$36*'مفروضات مشترک'!$B$53/16000)) -> 33.324884 | F23: ⚠ همین عدد، آستانهٔ ICP است — میلیارد تومان در سال
B24: گردش مالی متناظر مشتری این سناریو | C24: =C6/'مفروضات مشترک'!$B$45/'مفروضات مشترک'!$B$41 -> 1658.88 | D24: =D6/'مفروضات مشترک'!$B$45/'مفروضات مشترک'!$B$41 -> 6220.8 | E24: =E6/'مفروضات مشترک'!$B$45/'مفروضات مشترک'!$B$41 -> 63037.44 | F24: خرج رسانه ÷ سهم رسانه از پاکت ÷ ۴٪ — میلیارد تومان
B25: گردش مالی حداقلی برای ورود به ICP | C25: =IF(ISNUMBER(C23),C23/'مفروضات مشترک'!$B$45/'مفروضات مشترک'!$B$41,"—") -> 4565.8717 | D25: =IF(ISNUMBER(D23),D23/'مفروضات مشترک'!$B$45/'مفروضات مشترک'!$B$41,"—") -> 2060.8214 | E25: =IF(ISNUMBER(E23),E23/'مفروضات مشترک'!$B$45/'مفروضات مشترک'!$B$41,"—") -> 1190.1744 | F25: ⚠ شاخص غربال فروش — از خرج تبلیغات راحت‌تر پرسیده می‌شود
B26: آیا مشتری این سناریو از آستانه بزرگ‌تر است | C26: =IF(ISNUMBER(C23),IF(C6>=C23,"بله","⚠ نه — این مشتری زیر آستانهٔ اقتصادی است"),"—") -> ⚠ نه — این مشتری زیر آستانهٔ اقتصادی است | D26: =IF(ISNUMBER(D23),IF(D6>=D23,"بله","⚠ نه — این مشتری زیر آستانهٔ اقتصادی است"),"—") -> بله | E26: =IF(ISNUMBER(E23),IF(E6>=E23,"بله","⚠ نه — این مشتری زیر آستانهٔ اقتصادی است"),"—") -> بله | F26: اگر «نه» باشد، آن مشتری در ICP نیست
B27: بازگشت سرمایه
B28: هزینهٔ استقرار برای ما | C28: ='مفروضات مشترک'!$B$29/22*'مفروضات مشترک'!$B$53 -> 161.21212 | D28: ='مفروضات مشترک'!$B$29/22*'مفروضات مشترک'!$B$53 -> 161.21212 | E28: ='مفروضات مشترک'!$B$29/22*'مفروضات مشترک'!$B$53 -> 161.21212 | F28: نفر-روز ÷ ۲۲ × نرخ نفر-ماه
B29: سود خالص استقرار | C29: =C12-C28 -> 63.787879 | D29: =D12-D28 -> 63.787879 | E29: =E12-E28 -> 63.787879 | F29: درآمد استقرار − هزینهٔ استقرار
B30: CAC | C30: ='مفروضات مشترک'!$B$39 -> 60 | D30: ='مفروضات مشترک'!$B$39 -> 60 | E30: ='مفروضات مشترک'!$B$39 -> 60 | F30: از مفروضات مشترک
B31: سرمایهٔ اولیهٔ هر مشتری | C31: =C30-C29 -> -3.7878788 | D31: =D30-D29 -> -3.7878788 | E31: =E30-E29 -> -3.7878788 | F31: CAC − سود خالص استقرار
B32: دورهٔ بازگشت | C32: =IF(C20<=0,"بازنمی‌گردد",IF(C31<=0,0,C31/C20)) -> بازنمی‌گردد | D32: =IF(D20<=0,"بازنمی‌گردد",IF(D31<=0,0,D31/D20)) -> 0 | E32: =IF(E20<=0,"بازنمی‌گردد",IF(E31<=0,0,E31/E20)) -> 0 | F32: سرمایهٔ اولیه ÷ حاشیهٔ ماهانه
B33: ارزش طول عمر (LTV) | C33: =IF(سناریوها!$C$16=0,"—",C20*12/سناریوها!$C$16) -> -344.99805 | D33: =IF(سناریوها!$D$16=0,"—",D20*12/سناریوها!$D$16) -> 10595.592 | E33: =IF(سناریوها!$E$16=0,"—",E20*12/سناریوها!$E$16) -> 331074.35 | F33: حاشیهٔ سالانه ÷ نرخ ریزش
B34: نسبت LTV به CAC | C34: =IF(C30=0,"—",C33/C30) -> -5.7499675 | D34: =IF(D30=0,"—",D33/D30) -> 176.59319 | E34: =IF(E30=0,"—",E33/E30) -> 5517.9058 | F34: زیر ۳ برابر هشدار است
B35: کنترل معناداری LTV/CAC | C35: =IF(C34>50,"⚠ این عدد در گزارش نقل نمی‌شود — محدودیت واقعی ظرفیت تحویل است، نه هزینهٔ جذب",IF(C34<3,"⚠ زیر ۳ برابر","در دامنهٔ معنادار")) -> ⚠ زیر ۳ برابر | D35: =IF(D34>50,"⚠ این عدد در گزارش نقل نمی‌شود — محدودیت واقعی ظرفیت تحویل است، نه هزینهٔ جذب",IF(D34<3,"⚠ زیر ۳ برابر","در دامنهٔ معنادار")) -> ⚠ این عدد در گزارش نقل نمی‌شود — محدودیت واقعی ظرفیت تحویل است، نه هزینهٔ جذب | E35: =IF(E34>50,"⚠ این عدد در گزارش نقل نمی‌شود — محدودیت واقعی ظرفیت تحویل است، نه هزینهٔ جذب",IF(E34<3,"⚠ زیر ۳ برابر","در دامنهٔ معنادار")) -> ⚠ این عدد در گزارش نقل نمی‌شود — محدودیت واقعی ظرفیت تحویل است، نه هزینهٔ جذب | F35: فروش B2B با تعداد مشتری کم، LTV/CAC را بی‌معنی بزرگ می‌کند
B36: هزینهٔ کل مالکیت مشتری (TCO) — سمت او، نه سود ما
B37: سرمایهٔ سرور و GPU مشتری — سرشکن سالانه | C37: ='مفروضات مشترک'!$B$47/'مفروضات مشترک'!$B$48*'مفروضات مشترک'!$B$32 -> 150 | D37: ='مفروضات مشترک'!$B$47/'مفروضات مشترک'!$B$48*'مفروضات مشترک'!$B$32 -> 150 | E37: ='مفروضات مشترک'!$B$47/'مفروضات مشترک'!$B$48*'مفروضات مشترک'!$B$32 -> 150 | F37: فقط برای مشتری On-Premise · وزن‌دار به سهمش
B38: TCO سالانهٔ مشتری | C38: =C8+C12+C37 -> 653.69184 | D38: =D8+D12+D37 -> 2465.1888 | E38: =E8+E12+E37 -> 35675.966 | F38: لایسنس + استقرار + سرشکن سرور خودش
B39: TCO به‌عنوان درصد از خرج تبلیغات | C39: =C38/(سناریوها!$C$6*1000) -> 0.014073433 | D39: =D38/(سناریوها!$D$6*1000) -> 0.014152916 | E39: =E38/(سناریوها!$E$6*1000) -> 0.020212459 | F39: این عددی است که مشتری با آن تصمیم می‌گیرد، نه لایسنس تنها

Sheet مدل بدبین
A1: مدل ۲۴ماهه — سناریوی بدبین
A2: واحد: میلیون تومان · قرارداد جدید هر ماه به ظرفیت آزاد استقرار محدود است · ضریب تورم و ضریب قیمت هر ۱۲ ماه یک پله بالا می‌روند.
A4: ماه | B4: 1 | C4: 2 | D4: 3 | E4: 4 | F4: 5 | G4: 6 | H4: 7 | I4: 8 | J4: 9 | K4: 10 | L4: 11 | M4: 12 | N4: 13 | O4: 14 | P4: 15 | Q4: 16 | R4: 17 | S4: 18 | T4: 19 | U4: 20 | V4: 21 | W4: 22 | X4: 23 | Y4: 24
A5: ضرایب زمانی
A6: ضریب تورم هزینه | B6: =(1+'مفروضات مشترک'!$B$10)^INT((1-1)/12) -> 1 | C6: =(1+'مفروضات مشترک'!$B$10)^INT((2-1)/12) -> 1 | D6: =(1+'مفروضات مشترک'!$B$10)^INT((3-1)/12) -> 1 | E6: =(1+'مفروضات مشترک'!$B$10)^INT((4-1)/12) -> 1 | F6: =(1+'مفروضات مشترک'!$B$10)^INT((5-1)/12) -> 1 | G6: =(1+'مفروضات مشترک'!$B$10)^INT((6-1)/12) -> 1 | H6: =(1+'مفروضات مشترک'!$B$10)^INT((7-1)/12) -> 1 | I6: =(1+'مفروضات مشترک'!$B$10)^INT((8-1)/12) -> 1 | J6: =(1+'مفروضات مشترک'!$B$10)^INT((9-1)/12) -> 1 | K6: =(1+'مفروضات مشترک'!$B$10)^INT((10-1)/12) -> 1 | L6: =(1+'مفروضات مشترک'!$B$10)^INT((11-1)/12) -> 1 | M6: =(1+'مفروضات مشترک'!$B$10)^INT((12-1)/12) -> 1 | N6: =(1+'مفروضات مشترک'!$B$10)^INT((13-1)/12) -> 1.4 | O6: =(1+'مفروضات مشترک'!$B$10)^INT((14-1)/12) -> 1.4 | P6: =(1+'مفروضات مشترک'!$B$10)^INT((15-1)/12) -> 1.4 | Q6: =(1+'مفروضات مشترک'!$B$10)^INT((16-1)/12) -> 1.4 | R6: =(1+'مفروضات مشترک'!$B$10)^INT((17-1)/12) -> 1.4 | S6: =(1+'مفروضات مشترک'!$B$10)^INT((18-1)/12) -> 1.4 | T6: =(1+'مفروضات مشترک'!$B$10)^INT((19-1)/12) -> 1.4 | U6: =(1+'مفروضات مشترک'!$B$10)^INT((20-1)/12) -> 1.4 | V6: =(1+'مفروضات مشترک'!$B$10)^INT((21-1)/12) -> 1.4 | W6: =(1+'مفروضات مشترک'!$B$10)^INT((22-1)/12) -> 1.4 | X6: =(1+'مفروضات مشترک'!$B$10)^INT((23-1)/12) -> 1.4 | Y6: =(1+'مفروضات مشترک'!$B$10)^INT((24-1)/12) -> 1.4
A7: ضریب فهرست قیمت | B7: =(1+سناریوها!$C$10)^INT((1-1)/12) -> 1 | C7: =(1+سناریوها!$C$10)^INT((2-1)/12) -> 1 | D7: =(1+سناریوها!$C$10)^INT((3-1)/12) -> 1 | E7: =(1+سناریوها!$C$10)^INT((4-1)/12) -> 1 | F7: =(1+سناریوها!$C$10)^INT((5-1)/12) -> 1 | G7: =(1+سناریوها!$C$10)^INT((6-1)/12) -> 1 | H7: =(1+سناریوها!$C$10)^INT((7-1)/12) -> 1 | I7: =(1+سناریوها!$C$10)^INT((8-1)/12) -> 1 | J7: =(1+سناریوها!$C$10)^INT((9-1)/12) -> 1 | K7: =(1+سناریوها!$C$10)^INT((10-1)/12) -> 1 | L7: =(1+سناریوها!$C$10)^INT((11-1)/12) -> 1 | M7: =(1+سناریوها!$C$10)^INT((12-1)/12) -> 1 | N7: =(1+سناریوها!$C$10)^INT((13-1)/12) -> 1.3 | O7: =(1+سناریوها!$C$10)^INT((14-1)/12) -> 1.3 | P7: =(1+سناریوها!$C$10)^INT((15-1)/12) -> 1.3 | Q7: =(1+سناریوها!$C$10)^INT((16-1)/12) -> 1.3 | R7: =(1+سناریوها!$C$10)^INT((17-1)/12) -> 1.3 | S7: =(1+سناریوها!$C$10)^INT((18-1)/12) -> 1.3 | T7: =(1+سناریوها!$C$10)^INT((19-1)/12) -> 1.3 | U7: =(1+سناریوها!$C$10)^INT((20-1)/12) -> 1.3 | V7: =(1+سناریوها!$C$10)^INT((21-1)/12) -> 1.3 | W7: =(1+سناریوها!$C$10)^INT((22-1)/12) -> 1.3 | X7: =(1+سناریوها!$C$10)^INT((23-1)/12) -> 1.3 | Y7: =(1+سناریوها!$C$10)^INT((24-1)/12) -> 1.3
A8: ضریب فاز — سهم عرضه‌شده از بستهٔ کامل | B8: =IF(1>='مفروضات مشترک'!$B$18,'مفروضات مشترک'!$B$15,IF(1>='مفروضات مشترک'!$B$17,'مفروضات مشترک'!$B$14,IF(1>='مفروضات مشترک'!$B$16,'مفروضات مشترک'!$B$13,0))) -> 0 | C8: =IF(2>='مفروضات مشترک'!$B$18,'مفروضات مشترک'!$B$15,IF(2>='مفروضات مشترک'!$B$17,'مفروضات مشترک'!$B$14,IF(2>='مفروضات مشترک'!$B$16,'مفروضات مشترک'!$B$13,0))) -> 0 | D8: =IF(3>='مفروضات مشترک'!$B$18,'مفروضات مشترک'!$B$15,IF(3>='مفروضات مشترک'!$B$17,'مفروضات مشترک'!$B$14,IF(3>='مفروضات مشترک'!$B$16,'مفروضات مشترک'!$B$13,0))) -> 0 | E8: =IF(4>='مفروضات مشترک'!$B$18,'مفروضات مشترک'!$B$15,IF(4>='مفروضات مشترک'!$B$17,'مفروضات مشترک'!$B$14,IF(4>='مفروضات مشترک'!$B$16,'مفروضات مشترک'!$B$13,0))) -> 0 | F8: =IF(5>='مفروضات مشترک'!$B$18,'مفروضات مشترک'!$B$15,IF(5>='مفروضات مشترک'!$B$17,'مفروضات مشترک'!$B$14,IF(5>='مفروضات مشترک'!$B$16,'مفروضات مشترک'!$B$13,0))) -> 0 | G8: =IF(6>='مفروضات مشترک'!$B$18,'مفروضات مشترک'!$B$15,IF(6>='مفروضات مشترک'!$B$17,'مفروضات مشترک'!$B$14,IF(6>='مفروضات مشترک'!$B$16,'مفروضات مشترک'!$B$13,0))) -> 0.3 | H8: =IF(7>='مفروضات مشترک'!$B$18,'مفروضات مشترک'!$B$15,IF(7>='مفروضات مشترک'!$B$17,'مفروضات مشترک'!$B$14,IF(7>='مفروضات مشترک'!$B$16,'مفروضات مشترک'!$B$13,0))) -> 0.3 | I8: =IF(8>='مفروضات مشترک'!$B$18,'مفروضات مشترک'!$B$15,IF(8>='مفروضات مشترک'!$B$17,'مفروضات مشترک'!$B$14,IF(8>='مفروضات مشترک'!$B$16,'مفروضات مشترک'!$B$13,0))) -> 0.3 | J8: =IF(9>='مفروضات مشترک'!$B$18,'مفروضات مشترک'!$B$15,IF(9>='مفروضات مشترک'!$B$17,'مفروضات مشترک'!$B$14,IF(9>='مفروضات مشترک'!$B$16,'مفروضات مشترک'!$B$13,0))) -> 0.3 | K8: =IF(10>='مفروضات مشترک'!$B$18,'مفروضات مشترک'!$B$15,IF(10>='مفروضات مشترک'!$B$17,'مفروضات مشترک'!$B$14,IF(10>='مفروضات مشترک'!$B$16,'مفروضات مشترک'!$B$13,0))) -> 0.3 | L8: =IF(11>='مفروضات مشترک'!$B$18,'مفروضات مشترک'!$B$15,IF(11>='مفروضات مشترک'!$B$17,'مفروضات مشترک'!$B$14,IF(11>='مفروضات مشترک'!$B$16,'مفروضات مشترک'!$B$13,0))) -> 0.75 | M8: =IF(12>='مفروضات مشترک'!$B$18,'مفروضات مشترک'!$B$15,IF(12>='مفروضات مشترک'!$B$17,'مفروضات مشترک'!$B$14,IF(12>='مفروضات مشترک'!$B$16,'مفروضات مشترک'!$B$13,0))) -> 0.75 | N8: =IF(13>='مفروضات مشترک'!$B$18,'مفروضات مشترک'!$B$15,IF(13>='مفروضات مشترک'!$B$17,'مفروضات مشترک'!$B$14,IF(13>='مفروضات مشترک'!$B$16,'مفروضات مشترک'!$B$13,0))) -> 0.75 | O8: =IF(14>='مفروضات مشترک'!$B$18,'مفروضات مشترک'!$B$15,IF(14>='مفروضات مشترک'!$B$17,'مفروضات مشترک'!$B$14,IF(14>='مفروضات مشترک'!$B$16,'مفروضات مشترک'!$B$13,0))) -> 0.75 | P8: =IF(15>='مفروضات مشترک'!$B$18,'مفروضات مشترک'!$B$15,IF(15>='مفروضات مشترک'!$B$17,'مفروضات مشترک'!$B$14,IF(15>='مفروضات مشترک'!$B$16,'مفروضات مشترک'!$B$13,0))) -> 0.75 | Q8: =IF(16>='مفروضات مشترک'!$B$18,'مفروضات مشترک'!$B$15,IF(16>='مفروضات مشترک'!$B$17,'مفروضات مشترک'!$B$14,IF(16>='مفروضات مشترک'!$B$16,'مفروضات مشترک'!$B$13,0))) -> 0.75 | R8: =IF(17>='مفروضات مشترک'!$B$18,'مفروضات مشترک'!$B$15,IF(17>='مفروضات مشترک'!$B$17,'مفروضات مشترک'!$B$14,IF(17>='مفروضات مشترک'!$B$16,'مفروضات مشترک'!$B$13,0))) -> 0.75 | S8: =IF(18>='مفروضات مشترک'!$B$18,'مفروضات مشترک'!$B$15,IF(18>='مفروضات مشترک'!$B$17,'مفروضات مشترک'!$B$14,IF(18>='مفروضات مشترک'!$B$16,'مفروضات مشترک'!$B$13,0))) -> 0.75 | T8: =IF(19>='مفروضات مشترک'!$B$18,'مفروضات مشترک'!$B$15,IF(19>='مفروضات مشترک'!$B$17,'مفروضات مشترک'!$B$14,IF(19>='مفروضات مشترک'!$B$16,'مفروضات مشترک'!$B$13,0))) -> 1 | U8: =IF(20>='مفروضات مشترک'!$B$18,'مفروضات مشترک'!$B$15,IF(20>='مفروضات مشترک'!$B$17,'مفروضات مشترک'!$B$14,IF(20>='مفروضات مشترک'!$B$16,'مفروضات مشترک'!$B$13,0))) -> 1 | V8: =IF(21>='مفروضات مشترک'!$B$18,'مفروضات مشترک'!$B$15,IF(21>='مفروضات مشترک'!$B$17,'مفروضات مشترک'!$B$14,IF(21>='مفروضات مشترک'!$B$16,'مفروضات مشترک'!$B$13,0))) -> 1 | W8: =IF(22>='مفروضات مشترک'!$B$18,'مفروضات مشترک'!$B$15,IF(22>='مفروضات مشترک'!$B$17,'مفروضات مشترک'!$B$14,IF(22>='مفروضات مشترک'!$B$16,'مفروضات مشترک'!$B$13,0))) -> 1 | X8: =IF(23>='مفروضات مشترک'!$B$18,'مفروضات مشترک'!$B$15,IF(23>='مفروضات مشترک'!$B$17,'مفروضات مشترک'!$B$14,IF(23>='مفروضات مشترک'!$B$16,'مفروضات مشترک'!$B$13,0))) -> 1 | Y8: =IF(24>='مفروضات مشترک'!$B$18,'مفروضات مشترک'!$B$15,IF(24>='مفروضات مشترک'!$B$17,'مفروضات مشترک'!$B$14,IF(24>='مفروضات مشترک'!$B$16,'مفروضات مشترک'!$B$13,0))) -> 1
A9: قیف فروش
A10: لید واجد شرایط | B10: =IF(1>='مفروضات مشترک'!$B$24,سناریوها!$C$12,0) -> 0 | C10: =IF(2>='مفروضات مشترک'!$B$24,سناریوها!$C$12,0) -> 0 | D10: =IF(3>='مفروضات مشترک'!$B$24,سناریوها!$C$12,0) -> 0 | E10: =IF(4>='مفروضات مشترک'!$B$24,سناریوها!$C$12,0) -> 0 | F10: =IF(5>='مفروضات مشترک'!$B$24,سناریوها!$C$12,0) -> 0 | G10: =IF(6>='مفروضات مشترک'!$B$24,سناریوها!$C$12,0) -> 2 | H10: =IF(7>='مفروضات مشترک'!$B$24,سناریوها!$C$12,0) -> 2 | I10: =IF(8>='مفروضات مشترک'!$B$24,سناریوها!$C$12,0) -> 2 | J10: =IF(9>='مفروضات مشترک'!$B$24,سناریوها!$C$12,0) -> 2 | K10: =IF(10>='مفروضات مشترک'!$B$24,سناریوها!$C$12,0) -> 2 | L10: =IF(11>='مفروضات مشترک'!$B$24,سناریوها!$C$12,0) -> 2 | M10: =IF(12>='مفروضات مشترک'!$B$24,سناریوها!$C$12,0) -> 2 | N10: =IF(13>='مفروضات مشترک'!$B$24,سناریوها!$C$12,0) -> 2 | O10: =IF(14>='مفروضات مشترک'!$B$24,سناریوها!$C$12,0) -> 2 | P10: =IF(15>='مفروضات مشترک'!$B$24,سناریوها!$C$12,0) -> 2 | Q10: =IF(16>='مفروضات مشترک'!$B$24,سناریوها!$C$12,0) -> 2 | R10: =IF(17>='مفروضات مشترک'!$B$24,سناریوها!$C$12,0) -> 2 | S10: =IF(18>='مفروضات مشترک'!$B$24,سناریوها!$C$12,0) -> 2 | T10: =IF(19>='مفروضات مشترک'!$B$24,سناریوها!$C$12,0) -> 2 | U10: =IF(20>='مفروضات مشترک'!$B$24,سناریوها!$C$12,0) -> 2 | V10: =IF(21>='مفروضات مشترک'!$B$24,سناریوها!$C$12,0) -> 2 | W10: =IF(22>='مفروضات مشترک'!$B$24,سناریوها!$C$12,0) -> 2 | X10: =IF(23>='مفروضات مشترک'!$B$24,سناریوها!$C$12,0) -> 2 | Y10: =IF(24>='مفروضات مشترک'!$B$24,سناریوها!$C$12,0) -> 2
A11: جلسهٔ ارزیابی | B11: =B10*سناریوها!$C$13 -> 0 | C11: =C10*سناریوها!$C$13 -> 0 | D11: =D10*سناریوها!$C$13 -> 0 | E11: =E10*سناریوها!$C$13 -> 0 | F11: =F10*سناریوها!$C$13 -> 0 | G11: =G10*سناریوها!$C$13 -> 0.8 | H11: =H10*سناریوها!$C$13 -> 0.8 | I11: =I10*سناریوها!$C$13 -> 0.8 | ... Y11: =Y10*سناریوها!$C$13 -> 0.8
A12: قرارداد بالقوه (پس از چرخهٔ فروش) | B12: =IF(1-سناریوها!$C$15<1,0,INDEX($B$11:$Y$11,1,MAX(1,ROUND(1-سناریوها!$C$15,0)))*سناریوها!$C$14) -> 0 | C12: =IF(2-سناریوها!$C$15<1,0,INDEX($B$11:$Y$11,1,MAX(1,ROUND(2-سناریوها!$C$15,0)))*سناریوها!$C$14) -> 0 | D12: =IF(3-سناریوها!$C$15<1,0,INDEX($B$11:$Y$11,1,MAX(1,ROUND(3-سناریوها!$C$15,0)))*سناریوها!$C$14) -> 0 | E12: =IF(4-سناریوها!$C$15<1,0,INDEX($B$11:$Y$11,1,MAX(1,ROUND(4-سناریوها!$C$15,0)))*سناریوها!$C$14) -> 0 | F12: =IF(5-سناریوها!$C$15<1,0,INDEX($B$11:$Y$11,1,MAX(1,ROUND(5-سناریوها!$C$15,0)))*سناریوها!$C$14) -> 0 | G12: =IF(6-سناریوها!$C$15<1,0,INDEX($B$11:$Y$11,1,MAX(1,ROUND(6-سناریوها!$C$15,0)))*سناریوها!$C$14) -> 0 | H12: =IF(7-سناریوها!$C$15<1,0,INDEX($B$11:$Y$11,1,MAX(1,ROUND(7-سناریوها!$C$15,0)))*سناریوها!$C$14) -> 0 | I12: =IF(8-سناریوها!$C$15<1,0,INDEX($B$11:$Y$11,1,MAX(1,ROUND(8-سناریوها!$C$15,0)))*سناریوها!$C$14) -> 0 | J12: =IF(9-سناریوها!$C$15<1,0,INDEX($B$11:$Y$11,1,MAX(1,ROUND(9-سناریوها!$C$15,0)))*سناریوها!$C$14) -> 0 | K12: =IF(10-سناریوها!$C$15<1,0,INDEX($B$11:$Y$11,1,MAX(1,ROUND(10-سناریوها!$C$15,0)))*سناریوها!$C$14) -> 0 | L12: =IF(11-سناریوها!$C$15<1,0,INDEX($B$11:$Y$11,1,MAX(1,ROUND(11-سناریوها!$C$15,0)))*سناریوها!$C$14) -> 0.12 | M12: =IF(12-سناریوها!$C$15<1,0,INDEX($B$11:$Y$11,1,MAX(1,ROUND(12-سناریوها!$C$15,0)))*سناریوها!$C$14) -> 0.12 | N12: =IF(13-سناریوها!$C$15<1,0,INDEX($B$11:$Y$11,1,MAX(1,ROUND(13-سناریوها!$C$15,0)))*سناریوها!$C$14) -> 0.12 | O12: =IF(14-سناریوها!$C$15<1,0,INDEX($B$11:$Y$11,1,MAX(1,ROUND(14-سناریوها!$C$15,0)))*سناریوها!$C$14) -> 0.12 | P12: =IF(15-سناریوها!$C$15<1,0,INDEX($B$11:$Y$11,1,MAX(1,ROUND(15-سناریوها!$C$15,0)))*سناریوها!$C$14) -> 0.12 | Q12: =IF(16-سناریوها!$C$15<1,0,INDEX($B$11:$Y$11,1,MAX(1,ROUND(16-سناریوها!$C$15,0)))*سناریوها!$C$14) -> 0.12 | R12: =IF(17-سناریوها!$C$15<1,0,INDEX($B$11:$Y$11,1,MAX(1,ROUND(17-سناریوها!$C$15,0)))*سناریوها!$C$14) -> 0.12 | S12: =IF(18-سناریوها!$C$15<1,0,INDEX($B$11:$Y$11,1,MAX(1,ROUND(18-سناریوها!$C$15,0)))*سناریوها!$C$14) -> 0.12 | T12: =IF(19-سناریوها!$C$15<1,0,INDEX($B$11:$Y$11,1,MAX(1,ROUND(19-سناریوها!$C$15,0)))*سناریوها!$C$14) -> 0.12 | U12: =IF(20-سناریوها!$C$15<1,0,INDEX($B$11:$Y$11,1,MAX(1,ROUND(20-سناریوها!$C$15,0)))*سناریوها!$C$14) -> 0.12 | V12: =IF(21-سناریوها!$C$15<1,0,INDEX($B$11:$Y$11,1,MAX(1,ROUND(21-سناریوها!$C$15,0)))*سناریوها!$C$14) -> 0.12 | W12: =IF(22-سناریوها!$C$15<1,0,INDEX($B$11:$Y$11,1,MAX(1,ROUND(22-سناریوها!$C$15,0)))*سناریوها!$C$14) -> 0.12 | X12: =IF(23-سناریوها!$C$15<1,0,INDEX($B$11:$Y$11,1,MAX(1,ROUND(23-سناریوها!$C$15,0)))*سناریوها!$C$14) -> 0.12 | Y12: =IF(24-سناریوها!$C$15<1,0,INDEX($B$11:$Y$11,1,MAX(1,ROUND(24-سناریوها!$C$15,0)))*سناریوها!$C$14) -> 0.12
A13: ظرفیت و قرارداد
A14: ظرفیت آزاد استقرار | B14: ='مفروضات مشترک'!$B$27/'مفروضات مشترک'!$B$28 -> 2 | C14: ='مفروضات مشترک'!$B$27/'مفروضات مشترک'!$B$28 -> 2 | D14: ='مفروضات مشترک'!$B$27/'مفروضات مشترک'!$B$28 -> 2 | E14: ='مفروضات مشترک'!$B$27/'مفروضات مشترک'!$B$28 -> 2 | F14: ='مفروضات مشترک'!$B$27/'مفروضات مشترک'!$B$28 -> 2 | G14: ='مفروضات مشترک'!$B$27/'مفروضات مشترک'!$B$28 -> 2 | H14: ='مفروضات مشترک'!$B$27/'مفروضات مشترک'!$B$28 -> 2 | I14: ='مفروضات مشترک'!$B$27/'مفروضات مشترک'!$B$28 -> 2 | ... Y14: ='مفروضات مشترک'!$B$27/'مفروضات مشترک'!$B$28 -> 2
A15: سقف مشتری از ظرفیت پشتیبانی | B15: =سناریوها!$C$18*'مفروضات مشترک'!$B$25*160/'اقتصاد واحد'!$C$15 -> 21.703851 | C15: =سناریوها!$C$18*'مفروضات مشترک'!$B$25*160/'اقتصاد واحد'!$C$15 -> 21.703851 | D15: =سناریوها!$C$18*'مفروضات مشترک'!$B$25*160/'اقتصاد واحد'!$C$15 -> 21.703851 | E15: =سناریوها!$C$18*'مفروضات مشترک'!$B$25*160/'اقتصاد واحد'!$C$15 -> 21.703851 | F15: =سناریوها!$C$18*'مفروضات مشترک'!$B$25*160/'اقتصاد واحد'!$C$15 -> 21.703851 | G15: =سناریوها!$C$18*'مفروضات مشترک'!$B$25*160/'اقتصاد واحد'!$C$15 -> 21.703851 | H15: =سناریوها!$C$18*'مفروضات مشترک'!$B$25*160/'اقتصاد واحد'!$C$15 -> 21.703851 | I15: =سناریوها!$C$18*'مفروضات مشترک'!$B$25*160/'اقتصاد واحد'!$C$15 -> 21.703851 | ... Y15: =سناریوها!$C$18*'مفروضات مشترک'!$B$25*160/'اقتصاد واحد'!$C$15 -> 21.703851
A16: قرارداد جدید (محدود به ظرفیت) | B16: =MIN(B12,B14) -> 0 | C16: =MIN(C12,C14) -> 0 | D16: =MIN(D12,D14) -> 0 | E16: =MIN(E12,E14) -> 0 | F16: =MIN(F12,F14) -> 0 | G16: =MIN(G12,G14) -> 0 | H16: =MIN(H12,H14) -> 0 | I16: =MIN(I12,I14) -> 0 | ... Y16: =MIN(Y12,Y14) -> 0.12
A17: قرارداد فعال (تجمعی، پس از ریزش) | B17: =MIN(B15,سناریوها!$C$7,B16) -> 0 | C17: =MIN(C15,سناریوها!$C$7,B17*(1-سناریوها!$C$16/12)+C16) -> 0 | D17: =MIN(D15,سناریوها!$C$7,C17*(1-سناریوها!$C$16/12)+D16) -> 0 | E17: =MIN(E15,سناریوها!$C$7,D17*(1-سناریوها!$C$16/12)+E16) -> 0 | F17: =MIN(F15,سناریوها!$C$7,E17*(1-سناریوها!$C$16/12)+F16) -> 0 | G17: =MIN(G15,سناریوها!$C$7,F17*(1-سناریوها!$C$16/12)+G16) -> 0 | H17: =MIN(H15,سناریوها!$C$7,G17*(1-سناریوها!$C$16/12)+H16) -> 0 | I17: =MIN(I15,سناریوها!$C$7,H17*(1-سناریوها!$C$16/12)+I16) -> 0 | J17: =MIN(J15,سناریوها!$C$7,I17*(1-سناریوها!$C$16/12)+J16) -> 0 | ... Y17: =MIN(Y15,سناریوها!$C$7,X17*(1-سناریوها!$C$16/12)+Y16) -> 1.4704161
A18: درآمد
A19: درآمد لایسنس | B19: =B17*'اقتصاد واحد'!$C$11*B7*B8 -> 0 | C19: =C17*'اقتصاد واحد'!$C$11*C7*C8 -> 0 | D19: =D17*'اقتصاد واحد'!$C$11*D7*D8 -> 0 | E19: =E17*'اقتصاد واحد'!$C$11*E7*E8 -> 0 | F19: =F17*'اقتصاد واحد'!$C$11*F7*F8 -> 0 | G19: =G17*'اقتصاد واحد'!$C$11*G7*G8 -> 0 | H19: =H17*'اقتصاد واحد'!$C$11*H7*H8 -> 0 | I19: =I17*'اقتصاد واحد'!$C$11*I7*I8 -> 0 | ... Y19: =Y17*'اقتصاد واحد'!$C$11*Y7*Y8 -> 44.394237
A20: درآمد استقرار | B20: =B16*'اقتصاد واحد'!$C$12*B7 -> 0 | C20: =C16*'اقتصاد واحد'!$C$12*C7 -> 0 | D20: =D16*'اقتصاد واحد'!$C$12*D7 -> 0 | E20: =E16*'اقتصاد واحد'!$C$12*E7 -> 0 | F20: =F16*'اقتصاد واحد'!$C$12*F7 -> 0 | G20: =G16*'اقتصاد واحد'!$C$12*G7 -> 0 | H20: =H16*'اقتصاد واحد'!$C$12*H7 -> 0 | I20: =I16*'اقتصاد واحد'!$C$12*I7 -> 0 | ... Y20: =Y16*'اقتصاد واحد'!$C$12*Y7 -> 35.1
A21: درآمد کل | B21: =B19+B20 -> 0 | C21: =C19+C20 -> 0 | D21: =D19+D20 -> 0 | E21: =E19+E20 -> 0 | F21: =F19+F20 -> 0 | G21: =G19+G20 -> 0 | H21: =H19+H20 -> 0 | I21: =I19+I20 -> 0 | ... Y21: =Y19+Y20 -> 79.494237
A22: هزینه
A23: هزینهٔ توسعه | B23: =('مفروضات مشترک'!$B$52*B6)*(IF(AND(1>'مفروضات مشترک'!$B$16-'مفروضات مشترک'!$B$23-1,1<='مفروضات مشترک'!$B$16-1),'مفروضات مشترک'!$B$20/'مفروضات مشترک'!$B$23,0)+IF(AND(1>'مفروضات مشترک'!$B$17-'مفروضات مشترک'!$B$23-1,1<='مفروضات مشترک'!$B$17-1),'مفروضات مشترک'!$B$21/'مفروضات مشترک'!$B$23,0)+IF(AND(1>'مفروضات مشترک'!$B$18-'مفروضات مشترک'!$B$23-1,1<='مفروضات مشترک'!$B$18-1),'مفروضات مشترک'!$B$22/'مفروضات مشترک'!$B$23,0)) -> 414.4 | C23: =('مفروضات مشترک'!$B$52*C6)*(IF(AND(2>'مفروضات مشترک'!$B$16-'مفروضات مشترک'!$B$23-1,2<='مفروضات مشترک'!$B$16-1),'مفروضات مشترک'!$B$20/'مفروضات مشترک'!$B$23,0)+IF(AND(2>'مفروضات مشترک'!$B$17-'مفروضات مشترک'!$B$23-1,2<='مفروضات مشترک'!$B$17-1),'مفروضات مشترک'!$B$21/'مفروضات مشترک'!$B$23,0)+IF(AND(2>'مفروضات مشترک'!$B$18-'مفروضات مشترک'!$B$23-1,2<='مفروضات مشترک'!$B$18-1),'مفروضات مشترک'!$B$22/'مفروضات مشترک'!$B$23,0)) -> 414.4 | D23: =('مفروضات مشترک'!$B$52*D6)*(IF(AND(3>'مفروضات مشترک'!$B$16-'مفروضات مشترک'!$B$23-1,3<='مفروضات مشترک'!$B$16-1),'مفروضات مشترک'!$B$20/'مفروضات مشترک'!$B$23,0)+IF(AND(3>'مفروضات مشترک'!$B$17-'مفروضات مشترک'!$B$23-1,3<='مفروضات مشترک'!$B$17-1),'مفروضات مشترک'!$B$21/'مفروضات مشترک'!$B$23,0)+IF(AND(3>'مفروضات مشترک'!$B$18-'مفروضات مشترک'!$B$23-1,3<='مفروضات مشترک'!$B$18-1),'مفروضات مشترک'!$B$22/'مفروضات مشترک'!$B$23,0)) -> 414.4 | E23: =('مفروضات مشترک'!$B$52*E6)*(IF(AND(4>'مفروضات مشترک'!$B$16-'مفروضات مشترک'!$B$23-1,4<='مفروضات مشترک'!$B$16-1),'مفروضات مشترک'!$B$20/'مفروضات مشترک'!$B$23,0)+IF(AND(4>'مفروضات مشترک'!$B$17-'مفروضات مشترک'!$B$23-1,4<='مفروضات مشترک'!$B$17-1),'مفروضات مشترک'!$B$21/'مفروضات مشترک'!$B$23,0)+IF(AND(4>'مفروضات مشترک'!$B$18-'مفروضات مشترک'!$B$23-1,4<='مفروضات مشترک'!$B$18-1),'مفروضات مشترک'!$B$22/'مفروضات مشترک'!$B$23,0)) -> 414.4 | F23: =('مفروضات مشترک'!$B$52*F6)*(IF(AND(5>'مفروضات مشترک'!$B$16-'مفروضات مشترک'!$B$23-1,5<='مفروضات مشترک'!$B$16-1),'مفروضات مشترک'!$B$20/'مفروضات مشترک'!$B$23,0)+IF(AND(5>'مفروضات مشترک'!$B$17-'مفروضات مشترک'!$B$23-1,5<='مفروضات مشترک'!$B$17-1),'مفروضات مشترک'!$B$21/'مفروضات مشترک'!$B$23,0)+IF(AND(5>'مفروضات مشترک'!$B$18-'مفروضات مشترک'!$B$23-1,5<='مفروضات مشترک'!$B$18-1),'مفروضات مشترک'!$B$22/'مفروضات مشترک'!$B$23,0)) -> 414.4 | G23: =('مفروضات مشترک'!$B$52*G6)*(IF(AND(6>'مفروضات مشترک'!$B$16-'مفروضات مشترک'!$B$23-1,6<='مفروضات مشترک'!$B$16-1),'مفروضات مشترک'!$B$20/'مفروضات مشترک'!$B$23,0)+IF(AND(6>'مفروضات مشترک'!$B$17-'مفروضات مشترک'!$B$23-1,6<='مفروضات مشترک'!$B$17-1),'مفروضات مشترک'!$B$21/'مفروضات مشترک'!$B$23,0)+IF(AND(6>'مفروضات مشترک'!$B$18-'مفروضات مشترک'!$B$23-1,6<='مفروضات مشترک'!$B$18-1),'مفروضات مشترک'!$B$22/'مفروضات مشترک'!$B$23,0)) -> 745.92 | H23: =('مفروضات مشترک'!$B$52*H6)*(IF(AND(7>'مفروضات مشترک'!$B$16-'مفروضات مشترک'!$B$23-1,7<='مفروضات مشترک'!$B$16-1),'مفروضات مشترک'!$B$20/'مفروضات مشترک'!$B$23,0)+IF(AND(7>'مفروضات مشترک'!$B$17-'مفروضات مشترک'!$B$23-1,7<='مفروضات مشترک'!$B$17-1),'مفروضات مشترک'!$B$21/'مفروضات مشترک'!$B$23,0)+IF(AND(7>'مفروضات مشترک'!$B$18-'مفروضات مشترک'!$B$23-1,7<='مفروضات مشترک'!$B$18-1),'مفروضات مشترک'!$B$22/'مفروضات مشترک'!$B$23,0)) -> 745.92 | I23: =('مفروضات مشترک'!$B$52*I6)*(IF(AND(8>'مفروضات مشترک'!$B$16-'مفروضات مشترک'!$B$23-1,8<='مفروضات مشترک'!$B$16-1),'مفروضات مشترک'!$B$20/'مفروضات مشترک'!$B$23,0)+IF(AND(8>'مفروضات مشترک'!$B$17-'مفروضات مشترک'!$B$23-1,8<='مفروضات مشترک'!$B$17-1),'مفروضات مشترک'!$B$21/'مفروضات مشترک'!$B$23,0)+IF(AND(8>'مفروضات مشترک'!$B$18-'مفروضات مشترک'!$B$23-1,8<='مفروضات مشترک'!$B$18-1),'مفروضات مشترک'!$B$22/'مفروضات مشترک'!$B$23,0)) -> 745.92 | J23: =('مفروضات مشترک'!$B$52*J6)*(IF(AND(9>'مفروضات مشترک'!$B$16-'مفروضات مشترک'!$B$23-1,9<='مفروضات مشترک'!$B$16-1),'مفروضات مشترک'!$B$20/'مفروضات مشترک'!$B$23,0)+IF(AND(9>'مفروضات مشترک'!$B$17-'مفروضات مشترک'!$B$23-1,9<='مفروضات مشترک'!$B$17-1),'مفروضات مشترک'!$B$21/'مفروضات مشترک'!$B$23,0)+IF(AND(9>'مفروضات مشترک'!$B$18-'مفروضات مشترک'!$B$23-1,9<='مفروضات مشترک'!$B$18-1),'مفروضات مشترک'!$B$22/'مفروضات مشترک'!$B$23,0)) -> 745.92 | K23: =('مفروضات مشترک'!$B$52*K6)*(IF(AND(10>'مفروضات مشترک'!$B$16-'مفروضات مشترک'!$B$23-1,10<='مفروضات مشترک'!$B$16-1),'مفروضات مشترک'!$B$20/'مفروضات مشترک'!$B$23,0)+IF(AND(10>'مفروضات مشترک'!$B$17-'مفروضات مشترک'!$B$23-1,10<='مفروضات مشترک'!$B$17-1),'مفروضات مشترک'!$B$21/'مفروضات مشترک'!$B$23,0)+IF(AND(10>'مفروضات مشترک'!$B$18-'مفروضات مشترک'!$B$23-1,10<='مفروضات مشترک'!$B$18-1),'مفروضات مشترک'!$B$22/'مفروضات مشترک'!$B$23,0)) -> 745.92 | L23: =('مفروضات مشترک'!$B$52*L6)*(IF(AND(11>'مفروضات مشترک'!$B$16-'مفروضات مشترک'!$B$23-1,11<='مفروضات مشترک'!$B$16-1),'مفروضات مشترک'!$B$20/'مفروضات مشترک'!$B$23,0)+IF(AND(11>'مفروضات مشترک'!$B$17-'مفروضات مشترک'!$B$23-1,11<='مفروضات مشترک'!$B$17-1),'مفروضات مشترک'!$B$21/'مفروضات مشترک'!$B$23,0)+IF(AND(11>'مفروضات مشترک'!$B$18-'مفروضات مشترک'!$B$23-1,11<='مفروضات مشترک'!$B$18-1),'مفروضات مشترک'!$B$22/'مفروضات مشترک'!$B$23,0)) -> 0 | M23: =('مفروضات مشترک'!$B$52*M6)*(IF(AND(12>'مفروضات مشترک'!$B$16-'مفروضات مشترک'!$B$23-1,12<='مفروضات مشترک'!$B$16-1),'مفروضات مشترک'!$B$20/'مفروضات مشترک'!$B$23,0)+IF(AND(12>'مفروضات مشترک'!$B$17-'مفروضات مشترک'!$B$23-1,12<='مفروضات مشترک'!$B$17-1),'مفروضات مشترک'!$B$21/'مفروضات مشترک'!$B$23,0)+IF(AND(12>'مفروضات مشترک'!$B$18-'مفروضات مشترک'!$B$23-1,12<='مفروضات مشترک'!$B$18-1),'مفروضات مشترک'!$B$22/'مفروضات مشترک'!$B$23,0)) -> 0 | N23: =('مفروضات مشترک'!$B$52*N6)*(IF(AND(13>'مفروضات مشترک'!$B$16-'مفروضات مشترک'!$B$23-1,13<='مفروضات مشترک'!$B$16-1),'مفروضات مشترک'!$B$20/'مفروضات مشترک'!$B$23,0)+IF(AND(13>'مفروضات مشترک'!$B$17-'مفروضات مشترک'!$B$23-1,13<='مفروضات مشترک'!$B$17-1),'مفروضات مشترک'!$B$21/'مفروضات مشترک'!$B$23,0)+IF(AND(13>'مفروضات مشترک'!$B$18-'مفروضات مشترک'!$B$23-1,13<='مفروضات مشترک'!$B$18-1),'مفروضات مشترک'!$B$22/'مفروضات مشترک'!$B$23,0)) -> 0 | O23: =('مفروضات مشترک'!$B$52*O6)*(IF(AND(14>'مفروضات مشترک'!$B$16-'مفروضات مشترک'!$B$23-1,14<='مفروضات مشترک'!$B$16-1),'مفروضات مشترک'!$B$20/'مفروضات مشترک'!$B$23,0)+IF(AND(14>'مفروضات مشترک'!$B$17-'مفروضات مشترک'!$B$23-1,14<='مفروضات مشترک'!$B$17-1),'مفروضات مشترک'!$B$21/'مفروضات مشترک'!$B$23,0)+IF(AND(14>'مفروضات مشترک'!$B$18-'مفروضات مشترک'!$B$23-1,14<='مفروضات مشترک'!$B$18-1),'مفروضات مشترک'!$B$22/'مفروضات مشترک'!$B$23,0)) -> 1160.32 | P23: =('مفروضات مشترک'!$B$52*P6)*(IF(AND(15>'مفروضات مشترک'!$B$16-'مفروضات مشترک'!$B$23-1,15<='مفروضات مشترک'!$B$16-1),'مفروضات مشترک'!$B$20/'مفروضات مشترک'!$B$23,0)+IF(AND(15>'مفروضات مشترک'!$B$17-'مفروضات مشترک'!$B$23-1,15<='مفروضات مشترک'!$B$17-1),'مفروضات مشترک'!$B$21/'مفروضات مشترک'!$B$23,0)+IF(AND(15>'مفروضات مشترک'!$B$18-'مفروضات مشترک'!$B$23-1,15<='مفروضات مشترک'!$B$18-1),'مفروضات مشترک'!$B$22/'مفروضات مشترک'!$B$23,0)) -> 1160.32 | Q23: =('مفروضات مشترک'!$B$52*Q6)*(IF(AND(16>'مفروضات مشترک'!$B$16-'مفروضات مشترک'!$B$23-1,16<='مفروضات مشترک'!$B$16-1),'مفروضات مشترک'!$B$20/'مفروضات مشترک'!$B$23,0)+IF(AND(16>'مفروضات مشترک'!$B$17-'مفروضات مشترک'!$B$23-1,16<='مفروضات مشترک'!$B$17-1),'مفروضات مشترک'!$B$21/'مفروضات مشترک'!$B$23,0)+IF(AND(16>'مفروضات مشترک'!$B$18-'مفروضات مشترک'!$B$23-1,16<='مفروضات مشترک'!$B$18-1),'مفروضات مشترک'!$B$22/'مفروضات مشترک'!$B$23,0)) -> 1160.32 | R23: =('مفروضات مشترک'!$B$52*R6)*(IF(AND(17>'مفروضات مشترک'!$B$16-'مفروضات مشترک'!$B$23-1,17<='مفروضات مشترک'!$B$16-1),'مفروضات مشترک'!$B$20/'مفروضات مشترک'!$B$23,0)+IF(AND(17>'مفروضات مشترک'!$B$17-'مفروضات مشترک'!$B$23-1,17<='مفروضات مشترک'!$B$17-1),'مفروضات مشترک'!$B$21/'مفروضات مشترک'!$B$23,0)+IF(AND(17>'مفروضات مشترک'!$B$18-'مفروضات مشترک'!$B$23-1,17<='مفروضات مشترک'!$B$18-1),'مفروضات مشترک'!$B$22/'مفروضات مشترک'!$B$23,0)) -> 1160.32 | S23: =('مفروضات مشترک'!$B$52*S6)*(IF(AND(18>'مفروضات مشترک'!$B$16-'مفروضات مشترک'!$B$23-1,18<='مفروضات مشترک'!$B$16-1),'مفروضات مشترک'!$B$20/'مفروضات مشترک'!$B$23,0)+IF(AND(18>'مفروضات مشترک'!$B$17-'مفروضات مشترک'!$B$23-1,18<='مفروضات مشترک'!$B$17-1),'مفروضات مشترک'!$B$21/'مفروضات مشترک'!$B$23,0)+IF(AND(18>'مفروضات مشترک'!$B$18-'مفروضات مشترک'!$B$23-1,18<='مفروضات مشترک'!$B$18-1),'مفروضات مشترک'!$B$22/'مفروضات مشترک'!$B$23,0)) -> 1160.32 | T23: =('مفروضات مشترک'!$B$52*T6)*(IF(AND(19>'مفروضات مشترک'!$B$16-'مفروضات مشترک'!$B$23-1,19<='مفروضات مشترک'!$B$16-1),'مفروضات مشترک'!$B$20/'مفروضات مشترک'!$B$23,0)+IF(AND(19>'مفروضات مشترک'!$B$17-'مفروضات مشترک'!$B$23-1,19<='مفروضات مشترک'!$B$17-1),'مفروضات مشترک'!$B$21/'مفروضات مشترک'!$B$23,0)+IF(AND(19>'مفروضات مشترک'!$B$18-'مفروضات مشترک'!$B$23-1,19<='مفروضات مشترک'!$B$18-1),'مفروضات مشترک'!$B$22/'مفروضات مشترک'!$B$23,0)) -> 0 | U23: =('مفروضات مشترک'!$B$52*U6)*(IF(AND(20>'مفروضات مشترک'!$B$16-'مفروضات مشترک'!$B$23-1,20<='مفروضات مشترک'!$B$16-1),'مفروضات مشترک'!$B$20/'مفروضات مشترک'!$B$23,0)+IF(AND(20>'مفروضات مشترک'!$B$17-'مفروضات مشترک'!$B$23-1,20<='مفروضات مشترک'!$B$17-1),'مفروضات مشترک'!$B$21/'مفروضات مشترک'!$B$23,0)+IF(AND(20>'مفروضات مشترک'!$B$18-'مفروضات مشترک'!$B$23-1,20<='مفروضات مشترک'!$B$18-1),'مفروضات مشترک'!$B$22/'مفروضات مشترک'!$B$23,0)) -> 0 | V23: =('مفروضات مشترک'!$B$52*V6)*(IF(AND(21>'مفروضات مشترک'!$B$16-'مفروضات مشترک'!$B$23-1,21<='مفروضات مشترک'!$B$16-1),'مفروضات مشترک'!$B$20/'مفروضات مشترک'!$B$23,0)+IF(AND(21>'مفروضات مشترک'!$B$17-'مفروضات مشترک'!$B$23-1,21<='مفروضات مشترک'!$B$17-1),'مفروضات مشترک'!$B$21/'مفروضات مشترک'!$B$23,0)+IF(AND(21>'مفروضات مشترک'!$B$18-'مفروضات مشترک'!$B$23-1,21<='مفروضات مشترک'!$B$18-1),'مفروضات مشترک'!$B$22/'مفروضات مشترک'!$B$23,0)) -> 0 | W23: =('مفروضات مشترک'!$B$52*W6)*(IF(AND(22>'مفروضات مشترک'!$B$16-'مفروضات مشترک'!$B$23-1,22<='مفروضات مشترک'!$B$16-1),'مفروضات مشترک'!$B$20/'مفروضات مشترک'!$B$23,0)+IF(AND(22>'مفروضات مشترک'!$B$17-'مفروضات مشترک'!$B$23-1,22<='مفروضات مشترک'!$B$17-1),'مفروضات مشترک'!$B$21/'مفروضات مشترک'!$B$23,0)+IF(AND(22>'مفروضات مشترک'!$B$18-'مفروضات مشترک'!$B$23-1,22<='مفروضات مشترک'!$B$18-1),'مفروضات مشترک'!$B$22/'مفروضات مشترک'!$B$23,0)) -> 0 | X23: =('مفروضات مشترک'!$B$52*X6)*(IF(AND(23>'مفروضات مشترک'!$B$16-'مفروضات مشترک'!$B$23-1,23<='مفروضات مشترک'!$B$16-1),'مفروضات مشترک'!$B$20/'مفروضات مشترک'!$B$23,0)+IF(AND(23>'مفروضات مشترک'!$B$17-'مفروضات مشترک'!$B$23-1,23<='مفروضات مشترک'!$B$17-1),'مفروضات مشترک'!$B$21/'مفروضات مشترک'!$B$23,0)+IF(AND(23>'مفروضات مشترک'!$B$18-'مفروضات مشترک'!$B$23-1,23<='مفروضات مشترک'!$B$18-1),'مفروضات مشترک'!$B$22/'مفروضات مشترک'!$B$23,0)) -> 0 | Y23: =('مفروضات مشترک'!$B$52*Y6)*(IF(AND(24>'مفروضات مشترک'!$B$16-'مفروضات مشترک'!$B$23-1,24<='مفروضات مشترک'!$B$16-1),'مفروضات مشترک'!$B$20/'مفروضات مشترک'!$B$23,0)+IF(AND(24>'مفروضات مشترک'!$B$17-'مفروضات مشترک'!$B$23-1,24<='مفروضات مشترک'!$B$17-1),'مفروضات مشترک'!$B$21/'مفروضات مشترک'!$B$23,0)+IF(AND(24>'مفروضات مشترک'!$B$18-'مفروضات مشترک'!$B$23-1,24<='مفروضات مشترک'!$B$18-1),'مفروضات مشترک'!$B$22/'مفروضات مشترک'!$B$23,0)) -> 0
A24: هزینهٔ استقرار | B24: =B16*'اقتصاد واحد'!$C$28*B6 -> 0 | C24: =C16*'اقتصاد واحد'!$C$28*C6 -> 0 | D24: =D16*'اقتصاد واحد'!$C$28*D6 -> 0 | E24: =E16*'اقتصاد واحد'!$C$28*E6 -> 0 | F24: =F16*'اقتصاد واحد'!$C$28*F6 -> 0 | G24: =G16*'اقتصاد واحد'!$C$28*G6 -> 0 | H24: =H16*'اقتصاد واحد'!$C$28*H6 -> 0 | I24: =I16*'اقتصاد واحد'!$C$28*I6 -> 0 | ... Y24: =Y16*'اقتصاد واحد'!$C$28*Y6 -> 27.083636
A25: هزینهٔ متغیر مشتریان | B25: =B17*'اقتصاد واحد'!$C$18*B6*MAX(0.5,B8) -> 0 | C25: =C17*'اقتصاد واحد'!$C$18*C6*MAX(0.5,C8) -> 0 | D25: =D17*'اقتصاد واحد'!$C$18*D6*MAX(0.5,D8) -> 0 | E25: =E17*'اقتصاد واحد'!$C$18*E6*MAX(0.5,E8) -> 0 | F25: =F17*'اقتصاد واحد'!$C$18*F6*MAX(0.5,F8) -> 0 | G25: =G17*'اقتصاد واحد'!$C$18*G6*MAX(0.5,G8) -> 0 | H25: =H17*'اقتصاد واحد'!$C$18*H6*MAX(0.5,H8) -> 0 | I25: =I17*'اقتصاد واحد'!$C$18*I6*MAX(0.5,I8) -> 0 | ... Y25: =Y17*'اقتصاد واحد'!$C$18*Y6*MAX(0.5,Y8) -> 62.605156
A26: هزینهٔ فروش و جذب | B26: =B16*'مفروضات مشترک'!$B$39*B6 -> 0 | C26: =C16*'مفروضات مشترک'!$B$39*C6 -> 0 | D26: =D16*'مفروضات مشترک'!$B$39*D6 -> 0 | E26: =E16*'مفروضات مشترک'!$B$39*E6 -> 0 | F26: =F16*'مفروضات مشترک'!$B$39*F6 -> 0 | G26: =G16*'مفروضات مشترک'!$B$39*G6 -> 0 | H26: =H16*'مفروضات مشترک'!$B$39*H6 -> 0 | I26: =I16*'مفروضات مشترک'!$B$39*I6 -> 0 | ... Y26: =Y16*'مفروضات مشترک'!$B$39*Y6 -> 10.08
A27: هزینهٔ نگهداشت تیم | B27: =IF(1>='مفروضات مشترک'!$B$16,سناریوها!$C$18*'مفروضات مشترک'!$B$53*B6*MAX(0.6,B8),0) -> 0 | C27: =IF(2>='مفروضات مشترک'!$B$16,سناریوها!$C$18*'مفروضات مشترک'!$B$53*C6*MAX(0.6,C8),0) -> 0 | D27: =IF(3>='مفروضات مشترک'!$B$16,سناریوها!$C$18*'مفروضات مشترک'!$B$53*D6*MAX(0.6,D8),0) -> 0 | E27: =IF(4>='مفروضات مشترک'!$B$16,سناریوها!$C$18*'مفروضات مشترک'!$B$53*E6*MAX(0.6,E8),0) -> 0 | F27: =IF(5>='مفروضات مشترک'!$B$16,سناریوها!$C$18*'مفروضات مشترک'!$B$53*F6*MAX(0.6,F8),0) -> 0 | G27: =IF(6>='مفروضات مشترک'!$B$16,سناریوها!$C$18*'مفروضات مشترک'!$B$53*G6*MAX(0.6,G8),0) -> 532 | H27: =IF(7>='مفروضات مشترک'!$B$16,سناریوها!$C$18*'مفروضات مشترک'!$B$53*H6*MAX(0.6,H8),0) -> 532 | I27: =IF(8>='مفروضات مشترک'!$B$16,سناریوها!$C$18*'مفروضات مشترک'!$B$53*I6*MAX(0.6,I8),0) -> 532 | J27: =IF(9>='مفروضات مشترک'!$B$16,سناریوها!$C$18*'مفروضات مشترک'!$B$53*J6*MAX(0.6,J8),0) -> 532 | K27: =IF(10>='مفروضات مشترک'!$B$16,سناریوها!$C$18*'مفروضات مشترک'!$B$53*K6*MAX(0.6,K8),0) -> 532 | L27: =IF(11>='مفروضات مشترک'!$B$16,سناریوها!$C$18*'مفروضات مشترک'!$B$53*L6*MAX(0.6,L8),0) -> 665 | M27: =IF(12>='مفروضات مشترک'!$B$16,سناریوها!$C$18*'مفروضات مشترک'!$B$53*M6*MAX(0.6,M8),0) -> 665 | N27: =IF(13>='مفروضات مشترک'!$B$16,سناریوها!$C$18*'مفروضات مشترک'!$B$53*N6*MAX(0.6,N8),0) -> 931 | O27: =IF(14>='مفروضات مشترک'!$B$16,سناریوها!$C$18*'مفروضات مشترک'!$B$53*O6*MAX(0.6,O8),0) -> 931 | P27: =IF(15>='مفروضات مشترک'!$B$16,سناریوها!$C$18*'مفروضات مشترک'!$B$53*P6*MAX(0.6,P8),0) -> 931 | Q27: =IF(16>='مفروضات مشترک'!$B$16,سناریوها!$C$18*'مفروضات مشترک'!$B$53*Q6*MAX(0.6,Q8),0) -> 931 | R27: =IF(17>='مفروضات مشترک'!$B$16,سناریوها!$C$18*'مفروضات مشترک'!$B$53*R6*MAX(0.6,R8),0) -> 931 | S27: =IF(18>='مفروضات مشترک'!$B$16,سناریوها!$C$18*'مفروضات مشترک'!$B$53*S6*MAX(0.6,S8),0) -> 931 | T27: =IF(19>='مفروضات مشترک'!$B$16,سناریوها!$C$18*'مفروضات مشترک'!$B$53*T6*MAX(0.6,T8),0) -> 1241.3333 | U27: =IF(20>='مفروضات مشترک'!$B$16,سناریوها!$C$18*'مفروضات مشترک'!$B$53*U6*MAX(0.6,U8),0) -> 1241.3333 | V27: =IF(21>='مفروضات مشترک'!$B$16,سناریوها!$C$18*'مفروضات مشترک'!$B$53*V6*MAX(0.6,V8),0) -> 1241.3333 | W27: =IF(22>='مفروضات مشترک'!$B$16,سناریوها!$C$18*'مفروضات مشترک'!$B$53*W6*MAX(0.6,W8),0) -> 1241.3333 | X27: =IF(23>='مفروضات مشترک'!$B$16,سناریوها!$C$18*'مفروضات مشترک'!$B$53*X6*MAX(0.6,X8),0) -> 1241.3333 | Y27: =IF(24>='مفروضات مشترک'!$B$16,سناریوها!$C$18*'مفروضات مشترک'!$B$53*Y6*MAX(0.6,Y8),0) -> 1241.3333
A28: هزینهٔ کل | B28: =SUM(B23:B27) -> 414.4 | C28: =SUM(C23:C27) -> 414.4 | D28: =SUM(D23:D27) -> 414.4 | E28: =SUM(E23:E27) -> 414.4 | F28: =SUM(F23:F27) -> 414.4 | G28: =SUM(G23:G27) -> 1277.92 | H28: =SUM(H23:H27) -> 1277.92 | I28: =SUM(I23:I27) -> 1277.92 | ... Y28: =SUM(Y23:Y27) -> 1341.1021
A29: نتیجه — چهار مفهوم جدا
A30: حاشیهٔ مشارکت | B30: =B21-B25-B24 -> 0 | C30: =C21-C25-C24 -> 0 | D30: =D21-D25-D24 -> 0 | E30: =E21-E25-E24 -> 0 | F30: =F21-F25-F24 -> 0 | G30: =G21-G25-G24 -> 0 | H30: =H21-H25-H24 -> 0 | I30: =I21-I25-I24 -> 0 | ... Y30: =Y21-Y25-Y24 -> -10.194556
A31: سود عملیاتی | B31: =B21-B28 -> -414.4 | C31: =C21-C28 -> -414.4 | D31: =D21-D28 -> -414.4 | E31: =E21-E28 -> -414.4 | F31: =F21-F28 -> -414.4 | G31: =G21-G28 -> -1277.92 | H31: =H21-H28 -> -1277.92 | I31: =I21-I28 -> -1277.92 | ... Y31: =Y21-Y28 -> -1261.6079
A32: جریان نقدی تجمعی | B32: =B31 -> -414.4 | C32: =B32+C31 -> -828.8 | D32: =C32+D31 -> -1243.2 | E32: =D32+E31 -> -1657.6 | F32: =E32+F31 -> -2072 | G32: =F32+G31 -> -3349.92 | H32: =G32+H31 -> -4627.84 | I32: =H32+I31 -> -5905.76 | J32: =I32+J31 -> -7183.68 | ... Y32: =X32+Y31 -> -28779.719

Sheet مدل پایه
A1: مدل ۲۴ماهه — سناریوی پایه
A2: واحد: میلیون تومان · قرارداد جدید هر ماه به ظرفیت آزاد استقرار محدود است · ضریب تورم و ضریب قیمت هر ۱۲ ماه یک پله بالا می‌روند.
A4: ماه | B4: 1 | C4: 2 | D4: 3 | E4: 4 | F4: 5 | G4: 6 | H4: 7 | I4: 8 | J4: 9 | K4: 10 | L4: 11 | M4: 12 | N4: 13 | O4: 14 | P4: 15 | Q4: 16 | R4: 17 | S4: 18 | T4: 19 | U4: 20 | V4: 21 | W4: 22 | X4: 23 | Y4: 24
A5: ضرایب زمانی
A6: ضریب تورم هزینه | B6: =(1+'مفروضات مشترک'!$B$10)^INT((1-1)/12) -> 1 | C6: =(1+'مفروضات مشترک'!$B$10)^INT((2-1)/12) -> 1 | D6: =(1+'مفروضات مشترک'!$B$10)^INT((3-1)/12) -> 1 | E6: =(1+'مفروضات مشترک'!$B$10)^INT((4-1)/12) -> 1 | F6: =(1+'مفروضات مشترک'!$B$10)^INT((5-1)/12) -> 1 | G6: =(1+'مفروضات مشترک'!$B$10)^INT((6-1)/12) -> 1 | H6: =(1+'مفروضات مشترک'!$B$10)^INT((7-1)/12) -> 1 | I6: =(1+'مفروضات مشترک'!$B$10)^INT((8-1)/12) -> 1 | J6: =(1+'مفروضات مشترک'!$B$10)^INT((9-1)/12) -> 1 | K6: =(1+'مفروضات مشترک'!$B$10)^INT((10-1)/12) -> 1 | L6: =(1+'مفروضات مشترک'!$B$10)^INT((11-1)/12) -> 1 | M6: =(1+'مفروضات مشترک'!$B$10)^INT((12-1)/12) -> 1 | N6: =(1+'مفروضات مشترک'!$B$10)^INT((13-1)/12) -> 1.4 | O6: =(1+'مفروضات مشترک'!$B$10)^INT((14-1)/12) -> 1.4 | P6: =(1+'مفروضات مشترک'!$B$10)^INT((15-1)/12) -> 1.4 | Q6: =(1+'مفروضات مشترک'!$B$10)^INT((16-1)/12) -> 1.4 | R6: =(1+'مفروضات مشترک'!$B$10)^INT((17-1)/12) -> 1.4 | S6: =(1+'مفروضات مشترک'!$B$10)^INT((18-1)/12) -> 1.4 | T6: =(1+'مفروضات مشترک'!$B$10)^INT((19-1)/12) -> 1.4 | U6: =(1+'مفروضات مشترک'!$B$10)^INT((20-1)/12) -> 1.4 | V6: =(1+'مفروضات مشترک'!$B$10)^INT((21-1)/12) -> 1.4 | W6: =(1+'مفروضات مشترک'!$B$10)^INT((22-1)/12) -> 1.4 | X6: =(1+'مفروضات مشترک'!$B$10)^INT((23-1)/12) -> 1.4 | Y6: =(1+'مفروضات مشترک'!$B$10)^INT((24-1)/12) -> 1.4
A7: ضریب فهرست قیمت | B7: =(1+سناریوها!$D$10)^INT((1-1)/12) -> 1 | C7: =(1+سناریوها!$D$10)^INT((2-1)/12) -> 1 | D7: =(1+سناریوها!$D$10)^INT((3-1)/12) -> 1 | E7: =(1+سناریوها!$D$10)^INT((4-1)/12) -> 1 | F7: =(1+سناریوها!$D$10)^INT((5-1)/12) -> 1 | G7: =(1+سناریوها!$D$10)^INT((6-1)/12) -> 1 | H7: =(1+سناریوها!$D$10)^INT((7-1)/12) -> 1 | I7: =(1+سناریوها!$D$10)^INT((8-1)/12) -> 1 | J7: =(1+سناریوها!$D$10)^INT((9-1)/12) -> 1 | K7: =(1+سناریوها!$D$10)^INT((10-1)/12) -> 1 | L7: =(1+سناریوها!$D$10)^INT((11-1)/12) -> 1 | M7: =(1+سناریوها!$D$10)^INT((12-1)/12) -> 1 | N7: =(1+سناریوها!$D$10)^INT((13-1)/12) -> 1.325 | O7: =(1+سناریوها!$D$10)^INT((14-1)/12) -> 1.325 | P7: =(1+سناریوها!$D$10)^INT((15-1)/12) -> 1.325 | Q7: =(1+سناریوها!$D$10)^INT((16-1)/12) -> 1.325 | R7: =(1+سناریوها!$D$10)^INT((17-1)/12) -> 1.325 | S7: =(1+سناریوها!$D$10)^INT((18-1)/12) -> 1.325 | T7: =(1+سناریوها!$D$10)^INT((19-1)/12) -> 1.325 | U7: =(1+سناریوها!$D$10)^INT((20-1)/12) -> 1.325 | V7: =(1+سناریوها!$D$10)^INT((21-1)/12) -> 1.325 | W7: =(1+سناریوها!$D$10)^INT((22-1)/12) -> 1.325 | X7: =(1+سناریوها!$D$10)^INT((23-1)/12) -> 1.325 | Y7: =(1+سناریوها!$D$10)^INT((24-1)/12) -> 1.325
